Workbook

Sheet CLEANING
A1: NO | B1: STATUS | C1: A1 | D1: A2 | E1: A3 | F1: A4 | G1: A5 | H1: A6 | I1: A7 | J1: A8 | K1: A9 | L1: A10 | M1: A11 | N1: A12 | O1: A13 | P1: A14 | Q1: A15 | R1: A16 | S1: A17 | T1: A18 | U1: A19 | V1: A20 | W1: A21 | X1: A22 | Y1: A23 | Z1: A24 | AA1: A25 | AB1: A26 | AC1: A27 | AD1: A28 | AE1: A29 | AF1: A30 | AG1: A31 | AH1: A32 | AI1: A33
A2: 1 | B2: YES | C2: 5 | D2: 2 | E2: 2 | F2: 6 | G2: 3 | H2: 2 | I2: 6 | J2: 2 | K2: 1 | L2: 2 | M2: 1 | N2: 2 | O2: 3 | P2: 1 | Q2: 1 | R2: 1 | S2: 2 | T2: 3 | U2: 2 | V2: 4 | W2: 2 | X2: 3 | Y2: 2 | Z2: 4 | AA2: 2 | AB2: 3 | AC2: 2 | AD2: 4 | AE2: 2 | AF2: 4 | AG2: 2 | AH2: 4 | AI2: 1
A3: 2 | B3: NO | C3: 4 | D3: 1.55 | E3: 1.7435897 | F3: 5.025 | G3: 1.625 | H3: 1.835443 | I3: 5.9875 | J3: 1.8481013 | K3: 2.1139241 | L3: 3.175 | M3: 1.1 | N3: 2.3108108 | O3: 3.0625 | P3: 1.225 | Q3: 1.1518987 | R3: 1.4 | S3: 1.9382716 | T3: 3.382716 | U3: 1.962963 | V3: 4 | W3: 2 | X3: 3.1234568 | Y3: 1.962963 | Z3: 3.9506173 | AA3: 1.7530864 | AB3: 3.3580247 | AC3: 1.9876543 | AD3: 4 | AE3: 1.9753086 | AF3: 4 | AG3: 1.4625 | AH3: 4 | AI3: 1.7922078
A4: 3 | B4: NO | C4: 1 | D4: 1.55 | E4: 1.7435897 | F4: 5.025 | G4: 1.625 | H4: 1.835443 | I4: 5.9875 | J4: 1.8481013 | K4: 2.1139241 | L4: 3.175 | M4: 1.1 | N4: 2.3108108 | O4: 3.0625 | P4: 1.225 | Q4: 1.1518987 | R4: 1.4 | S4: 1.9382716 | T4: 3.382716 | U4: 1.962963 | V4: 4 | W4: 2 | X4: 3.1234568 | Y4: 1.962963 | Z4: 3.9506173 | AA4: 1.7530864 | AB4: 3.3580247 | AC4: 1.9876543 | AD4: 4 | AE4: 1.9753086 | AF4: 4 | AG4: 1.4625 | AH4: 4 | AI4: 1.7922078
A5: 4 | B5: NO | C5: 1 | D5: 1.55 | E5: 1.7435897 | F5: 5.025 | G5: 1.625 | H5: 1.835443 | I5: 5.9875 | J5: 1.8481013 | K5: 2.1139241 | L5: 3.175 | M5: 1.1 | N5: 2.3108108 | O5: 3.0625 | P5: 1.225 | Q5: 1.1518987 | R5: 1.4 | S5: 1.9382716 | T5: 3.382716 | U5: 1.962963 | V5: 4 | W5: 2 | X5: 3.1234568 | Y5: 1.962963 | Z5: 3.9506173 | AA5: 1.7530864 | AB5: 3.3580247 | AC5: 1.9876543 | AD5: 4 | AE5: 1.9753086 | AF5: 4 | AG5: 1.4625 | AH5: 4 | AI5: 1.7922078
A6: 5 | B6: NO | C6: 1 | D6: 1.55 | E6: 1.7435897 | F6: 5.025 | G6: 1.625 | H6: 1.835443 | I6: 5.9875 | J6: 1.8481013 | K6: 2.1139241 | L6: 3.175 | M6: 1.1 | N6: 2.3108108 | O6: 3.0625 | P6: 1.225 | Q6: 1.1518987 | R6: 1.4 | S6: 1.9382716 | T6: 3.382716 | U6: 1.962963 | V6: 4 | W6: 2 | X6: 3.1234568 | Y6: 1.962963 | Z6: 3.9506173 | AA6: 1.7530864 | AB6: 3.3580247 | AC6: 1.9876543 | AD6: 4 | AE6: 1.9753086 | AF6: 4 | AG6: 1.4625 | AH6: 4 | AI6: 1.7922078
A7: 6 | B7: NO | C7: 1 | D7: 1.55 | E7: 1.7435897 | F7: 5.025 | G7: 1.625 | H7: 1.835443 | I7: 5.9875 | J7: 1.8481013 | K7: 2.1139241 | L7: 3.175 | M7: 1.1 | N7: 2.3108108 | O7: 3.0625 | P7: 1.225 | Q7: 1.1518987 | R7: 1.4 | S7: 1.9382716 | T7: 3.382716 | U7: 1.962963 | V7: 4 | W7: 2 | X7: 3.1234568 | Y7: 1.962963 | Z7: 3.9506173 | AA7: 1.7530864 | AB7: 3.3580247 | AC7: 1.9876543 | AD7: 4 | AE7: 1.9753086 | AF7: 4 | AG7: 1.4625 | AH7: 4 | AI7: 1.7922078
A8: 7 | B8: NO | C8: 4 | D8: 2 | E8: 2 | F8: 6 | G8: 3 | H8: 2 | I8: 6 | J8: 2 | K8: 1 | L8: 2 | M8: 1 | N8: 2 | O8: 3 | P8: 1 | Q8: 1 | R8: 1 | S8: 2 | T8: 3 | U8: 2 | V8: 4 | W8: 2 | X8: 3 | Y8: 2 | Z8: 4 | AA8: 2 | AB8: 3 | AC8: 2 | AD8: 4 | AE8: 2 | AF8: 4 | AG8: 2 | AH8: 4 | AI8: 2
A9: 8 | B9: NO | C9: 1 | D9: 1.55 | E9: 1.7435897 | F9: 5.025 | G9: 1.625 | H9: 1.835443 | I9: 5.9875 | J9: 1.8481013 | K9: 2.1139241 | L9: 3.175 | M9: 1.1 | N9: 2.3108108 | O9: 3.0625 | P9: 1.225 | Q9: 1.1518987 | R9: 1.4 | S9: 1.9382716 | T9: 3.382716 | U9: 1.962963 | V9: 4 | W9: 2 | X9: 3.1234568 | Y9: 1.962963 | Z9: 3.9506173 | AA9: 1.7530864 | AB9: 3.3580247 | AC9: 1.9876543 | AD9: 4 | AE9: 1.9753086 | AF9: 4 | AG9: 1.4625 | AH9: 4 | AI9: 1.7922078
A10: 9 | B10: NO | C10: 2 | D10: 1 | E10: 1 | F10: 2 | G10: 1 | H10: 2 | I10: 6 | J10: 2 | K10: 2 | L10: 11 | M10: 1 | N10: 1 | O10: 3 | P10: 1 | Q10: 1 | R10: 1 | S10: 2 | T10: 4 | U10: 2 | V10: 4 | W10: 2 | X10: 4 | Y10: 2 | Z10: 4 | AA10: 1 | AB10: 4 | AC10: 2 | AD10: 4 | AE10: 2 | AF10: 4 | AG10: 1 | AH10: 4 | AI10: 2
A11: 10 | B11: YES | C11: 4 | D11: 1 | E11: 1 | F11: 8 | G11: 3 | H11: 2 | I11: 6 | J11: 2 | K11: 2 | L11: 2 | M11: 1 | N11: 2 | O11: 3 | P11: 1 | Q11: 1 | R11: 1 | S11: 2 | T11: 4 | U11: 2 | V11: 4 | W11: 2 | X11: 3 | Y11: 2 | Z11: 4 | AA11: 2 | AB11: 3 | AC11: 2 | AD11: 4 | AE11: 2 | AF11: 4 | AG11: 1 | AH11: 4 | AI11: 2

Sheet NORMALISASI
A1: STATUS | B1: A1 | C1: A2 | D1: A3 | E1: A4 | F1: A5 | G1: A6 | H1: A7 | I1: A8 | J1: A9 | K1: A10 | L1: A11 | M1: A12 | N1: A13 | O1: A14 | P1: A15 | Q1: A16 | R1: A17 | S1: A18 | T1: A19 | U1: A20 | V1: A21 | W1: A22 | X1: A23 | Y1: A24 | Z1: A25 | AA1: A26 | AB1: A27 | AC1: A28 | AD1: A29 | AE1: A30 | AF1: A31 | AG1: A32 | AH1: A33
A2: YES | B2: 0.7 | C2: 0.2 | D2: 0.3 | E2: 0.7 | F2: 0.3 | G2: 1 | H2: 0.5 | I2: 1 | J2: 0.2 | K2: 0 | L2: 0 | M2: 0.2 | N2: 0.5 | O2: 0 | P2: 0 | Q2: 0 | R2: 1 | S2: 0 | T2: 1 | U2: 1 | V2: 1 | W2: 0 | X2: 1 | Y2: 1 | Z2: 1 | AA2: 0 | AB2: 1 | AC2: 1 | AD2: 1 | AE2: 1 | AF2: 1 | AG2: 1 | AH2: 0.5
A3: NO | B3: 0.5 | C3: 0.1 | D3: 0.2 | E3: 0.5 | F3: 0.1 | G3: 0.9 | H3: 0.55416667 | I3: 0.84810127 | J3: 0.42278481 | K3: 0.13055556 | L3: 0.05 | M3: 0.26216216 | N3: 0.515625 | O3: 0.075 | P3: 0.050632911 | Q3: 0.1 | R3: 0.9382716 | S3: 0.38271605 | T3: 0.96296296 | U3: 1 | V3: 1 | W3: 0.12345679 | X3: 0.96296296 | Y3: 0.95061728 | Z3: 0.75308642 | AA3: 0.35802469 | AB3: 0.98765432 | AC3: 1 | AD3: 0.97530864 | AE3: 1 | AF3: 0.4625 | AG3: 1 | AH3: 0.8961039
A4: NO | B4: 0 | C4: 0.1 | D4: 0.2 | E4: 0.5 | F4: 0.1 | G4: 0.9 | H4: 0.55416667 | I4: 0.84810127 | J4: 0.42278481 | K4: 0.13055556 | L4: 0.05 | M4: 0.26216216 | N4: 0.515625 | O4: 0.075 | P4: 0.050632911 | Q4: 0.1 | R4: 0.9382716 | S4: 0.38271605 | T4: 0.96296296 | U4: 1 | V4: 1 | W4: 0.12345679 | X4: 0.96296296 | Y4: 0.95061728 | Z4: 0.75308642 | AA4: 0.35802469 | AB4: 0.98765432 | AC4: 1 | AD4: 0.97530864 | AE4: 1 | AF4: 0.4625 | AG4: 1 | AH4: 0.8961039
A5: NO | B5: 0 | C5: 0.1 | D5: 0.2 | E5: 0.5 | F5: 0.1 | G5: 0.9 | H5: 0.55416667 | I5: 0.84810127 | J5: 0.42278481 | K5: 0.13055556 | L5: 0.05 | M5: 0.26216216 | N5: 0.515625 | O5: 0.075 | P5: 0.050632911 | Q5: 0.1 | R5: 0.9382716 | S5: 0.38271605 | T5: 0.96296296 | U5: 1 | V5: 1 | W5: 0.12345679 | X5: 0.96296296 | Y5: 0.95061728 | Z5: 0.75308642 | AA5: 0.35802469 | AB5: 0.98765432 | AC5: 1 | AD5: 0.97530864 | AE5: 1 | AF5: 0.4625 | AG5: 1 | AH5: 0.8961039
A6: NO | B6: 0 | C6: 0.1 | D6: 0.2 | E6: 0.5 | F6: 0.1 | G6: 0.9 | H6: 0.55416667 | I6: 0.84810127 | J6: 0.42278481 | K6: 0.13055556 | L6: 0.05 | M6: 0.26216216 | N6: 0.515625 | O6: 0.075 | P6: 0.050632911 | Q6: 0.1 | R6: 0.9382716 | S6: 0.38271605 | T6: 0.96296296 | U6: 1 | V6: 1 | W6: 0.12345679 | X6: 0.96296296 | Y6: 0.95061728 | Z6: 0.75308642 | AA6: 0.35802469 | AB6: 0.98765432 | AC6: 1 | AD6: 0.97530864 | AE6: 1 | AF6: 0.4625 | AG6: 1 | AH6: 0.8961039
A7: NO | B7: 0 | C7: 0.1 | D7: 0.2 | E7: 0.5 | F7: 0.1 | G7: 0.9 | H7: 0.55416667 | I7: 0.84810127 | J7: 0.42278481 | K7: 0.13055556 | L7: 0.05 | M7: 0.26216216 | N7: 0.515625 | O7: 0.075 | P7: 0.050632911 | Q7: 0.1 | R7: 0.9382716 | S7: 0.38271605 | T7: 0.96296296 | U7: 1 | V7: 1 | W7: 0.12345679 | X7: 0.96296296 | Y7: 0.95061728 | Z7: 0.75308642 | AA7: 0.35802469 | AB7: 0.98765432 | AC7: 1 | AD7: 0.97530864 | AE7: 1 | AF7: 0.4625 | AG7: 1 | AH7: 0.8961039
A8: NO | B8: 0.5 | C8: 0.2 | D8: 0.3 | E8: 0.7 | F8: 0.3 | G8: 1 | H8: 0.5 | I8: 1 | J8: 0.2 | K8: 0 | L8: 0 | M8: 0.2 | N8: 0.5 | O8: 0 | P8: 0 | Q8: 0 | R8: 1 | S8: 0 | T8: 1 | U8: 1 | V8: 1 | W8: 0 | X8: 1 | Y8: 1 | Z8: 1 | AA8: 0 | AB8: 1 | AC8: 1 | AD8: 1 | AE8: 1 | AF8: 1 | AG8: 1 | AH8: 1
A9: NO | B9: 0 | C9: 0.1 | D9: 0.2 | E9: 0.5 | F9: 0.1 | G9: 0.9 | H9: 0.55416667 | I9: 0.84810127 | J9: 0.42278481 | K9: 0.13055556 | L9: 0.05 | M9: 0.26216216 | N9: 0.515625 | O9: 0.075 | P9: 0.050632911 | Q9: 0.1 | R9: 0.9382716 | S9: 0.38271605 | T9: 0.96296296 | U9: 1 | V9: 1 | W9: 0.12345679 | X9: 0.96296296 | Y9: 0.95061728 | Z9: 0.75308642 | AA9: 0.35802469 | AB9: 0.98765432 | AC9: 1 | AD9: 0.97530864 | AE9: 1 | AF9: 0.4625 | AG9: 1 | AH9: 0.8961039
A10: NO | B10: 0.2 | C10: 0 | D10: 0 | E10: 0 | F10: 0 | G10: 1 | H10: 0.5 | I10: 1 | J10: 0.4 | K10: 1 | L10: 0 | M10: 0 | N10: 0.5 | O10: 0 | P10: 0 | Q10: 0 | R10: 1 | S10: 1 | T10: 1 | U10: 1 | V10: 1 | W10: 1 | X10: 1 | Y10: 1 | Z10: 0 | AA10: 1 | AB10: 1 | AC10: 1 | AD10: 1 | AE10: 1 | AF10: 0 | AG10: 1 | AH10: 1
A11: YES | B11: 0.5 | C11: 0 | D11: 0 | E11: 1 | F11: 0.3 | G11: 1 | H11: 0.5 | I11: 1 | J11: 0.4 | K11: 0 | L11: 0 | M11: 0.2 | N11: 0.5 | O11: 0 | P11: 0 | Q11: 0 | R11: 1 | S11: 1 | T11: 1 | U11: 1 | V11: 1 | W11: 0 | X11: 1 | Y11: 1 | Z11: 1 | AA11: 0 | AB11: 1 | AC11: 1 | AD11: 1 | AE11: 1 | AF11: 0 | AG11: 1 | AH11: 1
A12: NO | B12: 0.5 | C12: 0.2 | D12: 0.3 | E12: 0.7 | F12: 0 | G12: 1 | H12: 0.5 | I12: 1 | J12: 0.2 | K12: 0 | L12: 0 | M12: 1 | N12: 0.5 | O12: 0.3 | P12: 0 | Q12: 0 | R12: 1 | S12: 0 | T12: 1 | U12: 1 | V12: 1 | W12: 0 | X12: 1 | Y12: 1 | Z12: 0 | AA12: 0 | AB12: 1 | AC12: 1 | AD12: 1 | AE12: 1 | AF12: 1 | AG12: 1 | AH12: 1
A13: NO | B13: 0.5 | C13: 0.2 | D13: 0.3 | E13: 0.7 | F13: 0 | G13: 1 | H13: 0.5 | I13: 1 | J13: 0.4 | K13: 0 | L13: 0 | M13: 1 | N13: 1 | O13: 0.3 | P13: 0 | Q13: 0 | R13: 1 | S13: 1 | T13: 1 | U13: 1 | V13: 1 | W13: 0 | X13: 1 | Y13: 1 | Z13: 1 | AA13: 1 | AB13: 1 | AC13: 1 | AD13: 1 | AE13: 1 | AF13: 1 | AG13: 1 | AH13: 1
... A21: YES | B21: 0.5 | C21: 0 | D21: 0 | E21: 0.7 | F21: 0.3 | G21: 1 | H21: 0.5 | I21: 0 | J21: 0.2 | K21: 0.44444444 | L21: 1 | M21: 0.26216216 | N21: 0.5 | O21: 1 | P21: 1 | Q21: 0.75 | R21: 1 | S21: 1 | T21: 1 | U21: 1 | V21: 1 | W21: 1 | X21: 1 | Y21: 1 | Z21: 1 | AA21: 1 | AB21: 1 | AC21: 1 | AD21: 1 | AE21: 1 | AF21: 1 | AG21: 1 | AH21: 0

Sheet DATA TRAINING
A1: STATUS | B1: A1 | C1: A2 | D1: A3 | E1: A4 | F1: A5 | G1: A6 | H1: A7 | I1: A8 | J1: A9 | K1: A10 | L1: A11 | M1: A12 | N1: A13 | O1: A14 | P1: A15 | Q1: A16 | R1: A17 | S1: A18 | T1: A19 | U1: A20 | V1: A21 | W1: A22 | X1: A23 | Y1: A24 | Z1: A25 | AA1: A26 | AB1: A27 | AC1: A28 | AD1: A29 | AE1: A30 | AF1: A31 | AG1: A32 | AH1: A33
A2: YES | B2: 0.7 | C2: 0.2 | D2: 0.3 | E2: 0.7 | F2: 0.3 | G2: 1 | H2: 0.5 | I2: 1 | J2: 0.2 | K2: 0 | L2: 0 | M2: 0.2 | N2: 0.5 | O2: 0 | P2: 0 | Q2: 0 | R2: 1 | S2: 0 | T2: 1 | U2: 1 | V2: 1 | W2: 0 | X2: 1 | Y2: 1 | Z2: 1 | AA2: 0 | AB2: 1 | AC2: 1 | AD2: 1 | AE2: 1 | AF2: 1 | AG2: 1 | AH2: 0.5
A3: NO | B3: 0.5 | C3: 0.1 | D3: 0.2 | E3: 0.5 | F3: 0.1 | G3: 0.9 | H3: 0.55416667 | I3: 0.84810127 | J3: 0.42278481 | K3: 0.13055556 | L3: 0.05 | M3: 0.26216216 | N3: 0.515625 | O3: 0.075 | P3: 0.050632911 | Q3: 0.1 | R3: 0.9382716 | S3: 0.38271605 | T3: 0.96296296 | U3: 1 | V3: 1 | W3: 0.12345679 | X3: 0.96296296 | Y3: 0.95061728 | Z3: 0.75308642 | AA3: 0.35802469 | AB3: 0.98765432 | AC3: 1 | AD3: 0.97530864 | AE3: 1 | AF3: 0.4625 | AG3: 1 | AH3: 0.8961039
A4: NO | B4: 0 | C4: 0.1 | D4: 0.2 | E4: 0.5 | F4: 0.1 | G4: 0.9 | H4: 0.55416667 | I4: 0.84810127 | J4: 0.42278481 | K4: 0.13055556 | L4: 0.05 | M4: 0.26216216 | N4: 0.515625 | O4: 0.075 | P4: 0.050632911 | Q4: 0.1 | R4: 0.9382716 | S4: 0.38271605 | T4: 0.96296296 | U4: 1 | V4: 1 | W4: 0.12345679 | X4: 0.96296296 | Y4: 0.95061728 | Z4: 0.75308642 | AA4: 0.35802469 | AB4: 0.98765432 | AC4: 1 | AD4: 0.97530864 | AE4: 1 | AF4: 0.4625 | AG4: 1 | AH4: 0.8961039
A5: NO | B5: 0 | C5: 0.1 | D5: 0.2 | E5: 0.5 | F5: 0.1 | G5: 0.9 | H5: 0.55416667 | I5: 0.84810127 | J5: 0.42278481 | K5: 0.13055556 | L5: 0.05 | M5: 0.26216216 | N5: 0.515625 | O5: 0.075 | P5: 0.050632911 | Q5: 0.1 | R5: 0.9382716 | S5: 0.38271605 | T5: 0.96296296 | U5: 1 | V5: 1 | W5: 0.12345679 | X5: 0.96296296 | Y5: 0.95061728 | Z5: 0.75308642 | AA5: 0.35802469 | AB5: 0.98765432 | AC5: 1 | AD5: 0.97530864 | AE5: 1 | AF5: 0.4625 | AG5: 1 | AH5: 0.8961039
A6: NO | B6: 0 | C6: 0.1 | D6: 0.2 | E6: 0.5 | F6: 0.1 | G6: 0.9 | H6: 0.55416667 | I6: 0.84810127 | J6: 0.42278481 | K6: 0.13055556 | L6: 0.05 | M6: 0.26216216 | N6: 0.515625 | O6: 0.075 | P6: 0.050632911 | Q6: 0.1 | R6: 0.9382716 | S6: 0.38271605 | T6: 0.96296296 | U6: 1 | V6: 1 | W6: 0.12345679 | X6: 0.96296296 | Y6: 0.95061728 | Z6: 0.75308642 | AA6: 0.35802469 | AB6: 0.98765432 | AC6: 1 | AD6: 0.97530864 | AE6: 1 | AF6: 0.4625 | AG6: 1 | AH6: 0.8961039
A7: NO | B7: 0 | C7: 0.1 | D7: 0.2 | E7: 0.5 | F7: 0.1 | G7: 0.9 | H7: 0.55416667 | I7: 0.84810127 | J7: 0.42278481 | K7: 0.13055556 | L7: 0.05 | M7: 0.26216216 | N7: 0.515625 | O7: 0.075 | P7: 0.050632911 | Q7: 0.1 | R7: 0.9382716 | S7: 0.38271605 | T7: 0.96296296 | U7: 1 | V7: 1 | W7: 0.12345679 | X7: 0.96296296 | Y7: 0.95061728 | Z7: 0.75308642 | AA7: 0.35802469 | AB7: 0.98765432 | AC7: 1 | AD7: 0.97530864 | AE7: 1 | AF7: 0.4625 | AG7: 1 | AH7: 0.8961039

Sheet DATA TESTING
A1: STATUS | B1: A1 | C1: A2 | D1: A3 | E1: A4 | F1: A5 | G1: A6 | H1: A7 | I1: A8 | J1: A9 | K1: A10 | L1: A11 | M1: A12 | N1: A13 | O1: A14 | P1: A15 | Q1: A16 | R1: A17 | S1: A18 | T1: A19 | U1: A20 | V1: A21 | W1: A22 | X1: A23 | Y1: A24 | Z1: A25 | AA1: A26 | AB1: A27 | AC1: A28 | AD1: A29 | AE1: A30 | AF1: A31 | AG1: A32 | AH1: A33
A2: NO | B2: 0.5 | C2: 0.2 | D2: 0.3 | E2: 0.7 | F2: 0.3 | G2: 1 | H2: 0.5 | I2: 1 | J2: 0.2 | K2: 0 | L2: 0 | M2: 0.2 | N2: 0.5 | O2: 0 | P2: 0 | Q2: 0 | R2: 1 | S2: 0 | T2: 1 | U2: 1 | V2: 1 | W2: 0 | X2: 1 | Y2: 1 | Z2: 1 | AA2: 0 | AB2: 1 | AC2: 1 | AD2: 1 | AE2: 1 | AF2: 1 | AG2: 1 | AH2: 1
A3: NO | B3: 0 | C3: 0.1 | D3: 0.2 | E3: 0.5 | F3: 0.1 | G3: 0.9 | H3: 0.55416667 | I3: 0.84810127 | J3: 0.42278481 | K3: 0.13055556 | L3: 0.05 | M3: 0.26216216 | N3: 0.515625 | O3: 0.075 | P3: 0.050632911 | Q3: 0.1 | R3: 0.9382716 | S3: 0.38271605 | T3: 0.96296296 | U3: 1 | V3: 1 | W3: 0.12345679 | X3: 0.96296296 | Y3: 0.95061728 | Z3: 0.75308642 | AA3: 0.35802469 | AB3: 0.98765432 | AC3: 1 | AD3: 0.97530864 | AE3: 1 | AF3: 0.4625 | AG3: 1 | AH3: 0.8961039
A4: NO | B4: 0.2 | C4: 0 | D4: 0 | E4: 0 | F4: 0 | G4: 1 | H4: 0.5 | I4: 1 | J4: 0.4 | K4: 1 | L4: 0 | M4: 0 | N4: 0.5 | O4: 0 | P4: 0 | Q4: 0 | R4: 1 | S4: 1 | T4: 1 | U4: 1 | V4: 1 | W4: 1 | X4: 1 | Y4: 1 | Z4: 0 | AA4: 1 | AB4: 1 | AC4: 1 | AD4: 1 | AE4: 1 | AF4: 0 | AG4: 1 | AH4: 1
A5: YES | B5: 0.5 | C5: 0 | D5: 0 | E5: 1 | F5: 0.3 | G5: 1 | H5: 0.5 | I5: 1 | J5: 0.4 | K5: 0 | L5: 0 | M5: 0.2 | N5: 0.5 | O5: 0 | P5: 0 | Q5: 0 | R5: 1 | S5: 1 | T5: 1 | U5: 1 | V5: 1 | W5: 0 | X5: 1 | Y5: 1 | Z5: 1 | AA5: 0 | AB5: 1 | AC5: 1 | AD5: 1 | AE5: 1 | AF5: 0 | AG5: 1 | AH5: 1

Sheet NBC
A1: HO: 60% : 40 % yaitu 60% data treining dan 40% data testing. Menggunakan linear sampling
A3: No | B3: A1 | C3: A2 | D3: A3 | E3: A4 | F3: A5 | G3: A6 | H3: A7 | I3: A8 | J3: A9 | K3: A10 | L3: A11 | M3: A12 | N3: A13 | O3: A14 | P3: A15 | Q3: A16 | R3: A17 | S3: A18 | T3: A19 | U3: A20 | V3: A21 | W3: A22 | X3: A23 | Y3: A24 | Z3: A25 | AA3: A26 | AB3: A27 | AC3: A28 | AD3: A29 | AE3: A30 | AF3: A31 | AG3: A32 | AH3: A33 | AI3: CLASS
A4: D1 | B4: 0.7 | C4: 0.2 | D4: 0.3 | E4: 0.7 | F4: 0.3 | G4: 1 | H4: 0.5 | I4: 1 | J4: 0.2 | K4: 0 | L4: 0 | M4: 0.2 | N4: 0.5 | O4: 0 | P4: 0 | Q4: 0 | R4: 1 | S4: 0 | T4: 1 | U4: 1 | V4: 1 | W4: 0 | X4: 1 | Y4: 1 | Z4: 1 | AA4: 0 | AB4: 1 | AC4: 1 | AD4: 1 | AE4: 1 | AF4: 1 | AG4: 1 | AH4: 0.5 | AI4: YES
A5: D2 | B5: 0.5 | C5: 0.1 | D5: 0.2 | E5: 0.5 | F5: 0.1 | G5: 0.9 | H5: 0.55416667 | I5: 0.84810127 | J5: 0.42278481 | K5: 0.13055556 | L5: 0.05 | M5: 0.26216216 | N5: 0.515625 | O5: 0.075 | P5: 0.050632911 | Q5: 0.1 | R5: 0.9382716 | S5: 0.38271605 | T5: 0.96296296 | U5: 1 | V5: 1 | W5: 0.12345679 | X5: 0.96296296 | Y5: 0.95061728 | Z5: 0.75308642 | AA5: 0.35802469 | AB5: 0.98765432 | AC5: 1 | AD5: 0.97530864 | AE5: 1 | AF5: 0.4625 | AG5: 1 | AH5: 0.8961039 | AI5: NO
A6: D3 | B6: 0 | C6: 0.1 | D6: 0.2 | E6: 0.5 | F6: 0.1 | G6: 0.9 | H6: 0.55416667 | I6: 0.84810127 | J6: 0.42278481 | K6: 0.13055556 | L6: 0.05 | M6: 0.26216216 | N6: 0.515625 | O6: 0.075 | P6: 0.050632911 | Q6: 0.1 | R6: 0.9382716 | S6: 0.38271605 | T6: 0.96296296 | U6: 1 | V6: 1 | W6: 0.12345679 | X6: 0.96296296 | Y6: 0.95061728 | Z6: 0.75308642 | AA6: 0.35802469 | AB6: 0.98765432 | AC6: 1 | AD6: 0.97530864 | AE6: 1 | AF6: 0.4625 | AG6: 1 | AH6: 0.8961039 | AI6: NO
A7: D4 | B7: 0 | C7: 0.1 | D7: 0.2 | E7: 0.5 | F7: 0.1 | G7: 0.9 | H7: 0.55416667 | I7: 0.84810127 | J7: 0.42278481 | K7: 0.13055556 | L7: 0.05 | M7: 0.26216216 | N7: 0.515625 | O7: 0.075 | P7: 0.050632911 | Q7: 0.1 | R7: 0.9382716 | S7: 0.38271605 | T7: 0.96296296 | U7: 1 | V7: 1 | W7: 0.12345679 | X7: 0.96296296 | Y7: 0.95061728 | Z7: 0.75308642 | AA7: 0.35802469 | AB7: 0.98765432 | AC7: 1 | AD7: 0.97530864 | AE7: 1 | AF7: 0.4625 | AG7: 1 | AH7: 0.8961039 | AI7: NO
A8: D5 | B8: 0 | C8: 0.1 | D8: 0.2 | E8: 0.5 | F8: 0.1 | G8: 0.9 | H8: 0.55416667 | I8: 0.84810127 | J8: 0.42278481 | K8: 0.13055556 | L8: 0.05 | M8: 0.26216216 | N8: 0.515625 | O8: 0.075 | P8: 0.050632911 | Q8: 0.1 | R8: 0.9382716 | S8: 0.38271605 | T8: 0.96296296 | U8: 1 | V8: 1 | W8: 0.12345679 | X8: 0.96296296 | Y8: 0.95061728 | Z8: 0.75308642 | AA8: 0.35802469 | AB8: 0.98765432 | AC8: 1 | AD8: 0.97530864 | AE8: 1 | AF8: 0.4625 | AG8: 1 | AH8: 0.8961039 | AI8: NO
A9: D6 | B9: 0 | C9: 0.1 | D9: 0.2 | E9: 0.5 | F9: 0.1 | G9: 0.9 | H9: 0.55416667 | I9: 0.84810127 | J9: 0.42278481 | K9: 0.13055556 | L9: 0.05 | M9: 0.26216216 | N9: 0.515625 | O9: 0.075 | P9: 0.050632911 | Q9: 0.1 | R9: 0.9382716 | S9: 0.38271605 | T9: 0.96296296 | U9: 1 | V9: 1 | W9: 0.12345679 | X9: 0.96296296 | Y9: 0.95061728 | Z9: 0.75308642 | AA9: 0.35802469 | AB9: 0.98765432 | AC9: 1 | AD9: 0.97530864 | AE9: 1 | AF9: 0.4625 | AG9: 1 | AH9: 0.8961039 | AI9: NO
A10: D7 | B10: 0.5 | C10: 0.2 | D10: 0.3 | E10: 0.7 | F10: 0.3 | G10: 1 | H10: 0.5 | I10: 1 | J10: 0.2 | K10: 0 | L10: 0 | M10: 0.2 | N10: 0.5 | O10: 0 | P10: 0 | Q10: 0 | R10: 1 | S10: 0 | T10: 1 | U10: 1 | V10: 1 | W10: 0 | X10: 1 | Y10: 1 | Z10: 1 | AA10: 0 | AB10: 1 | AC10: 1 | AD10: 1 | AE10: 1 | AF10: 1 | AG10: 1 | AH10: 1 | AI10: ?
A11: D8 | B11: 0 | C11: 0.1 | D11: 0.2 | E11: 0.5 | F11: 0.1 | G11: 0.9 | H11: 0.55416667 | I11: 0.84810127 | J11: 0.42278481 | K11: 0.13055556 | L11: 0.05 | M11: 0.26216216 | N11: 0.515625 | O11: 0.075 | P11: 0.050632911 | Q11: 0.1 | R11: 0.9382716 | S11: 0.38271605 | T11: 0.96296296 | U11: 1 | V11: 1 | W11: 0.12345679 | X11: 0.96296296 | Y11: 0.95061728 | Z11: 0.75308642 | AA11: 0.35802469 | AB11: 0.98765432 | AC11: 1 | AD11: 0.97530864 | AE11: 1 | AF11: 0.4625 | AG11: 1 | AH11: 0.8961039 | AI11: ?
A12: D9 | B12: 0.2 | C12: 0 | D12: 0 | E12: 0 | F12: 0 | G12: 1 | H12: 0.5 | I12: 1 | J12: 0.4 | K12: 1 | L12: 0 | M12: 0 | N12: 0.5 | O12: 0 | P12: 0 | Q12: 0 | R12: 1 | S12: 1 | T12: 1 | U12: 1 | V12: 1 | W12: 1 | X12: 1 | Y12: 1 | Z12: 0 | AA12: 1 | AB12: 1 | AC12: 1 | AD12: 1 | AE12: 1 | AF12: 0 | AG12: 1 | AH12: 1 | AI12: ?
A13: D10 | B13: 0.5 | C13: 0 | D13: 0 | E13: 1 | F13: 0.3 | G13: 1 | H13: 0.5 | I13: 1 | J13: 0.4 | K13: 0 | L13: 0 | M13: 0.2 | N13: 0.5 | O13: 0 | P13: 0 | Q13: 0 | R13: 1 | S13: 1 | T13: 1 | U13: 1 | V13: 1 | W13: 0 | X13: 1 | Y13: 1 | Z13: 1 | AA13: 0 | AB13: 1 | AC13: 1 | AD13: 1 | AE13: 1 | AF13: 0 | AG13: 1 | AH13: 1 | AI13: ?
A16: Probabilitas | B16: YES | C16: NO | D16: Total Data
A17: Probabilitas Kelas | B17: =COUNTIFS(AI4:AI9,"YES") -> 1 | C17: =COUNTIFS(AI4:AI13,"NO") -> 5 | D17: =SUM(B17:C17) -> 6
A18: P(X) | B18: =B17/D17 -> 0.16666667 | C18: =C17/D17 -> 0.83333333
B20: A1 | C20: A2 | D20: A3 | E20: A4 | F20: A5 | G20: A6 | H20: A7 | I20: A8 | J20: A9 | K20: A10 | L20: A11 | M20: A12 | N20: A13 | O20: A14 | P20: A15 | Q20: A16 | R20: A17 | S20: A18 | T20: A19 | U20: A20 | V20: A21 | W20: A22 | X20: A23 | Y20: A24 | Z20: A25 | AA20: A26 | AB20: A27 | AC20: A28 | AD20: A29 | AE20: A30 | AF20: A31 | AG20: A32 | AH20: A33
A21: D7 | B21: 0.5 | C21: 0.2 | D21: 0.3 | E21: 0.7 | F21: 0.3 | G21: 1 | H21: 0.5 | I21: 1 | J21: 0.2 | K21: 0 | L21: 0 | M21: 0.2 | N21: 0.5 | O21: 0 | P21: 0 | Q21: 0 | R21: 1 | S21: 0 | T21: 1 | U21: 1 | V21: 1 | W21: 0 | X21: 1 | Y21: 1 | Z21: 1 | AA21: 0 | AB21: 1 | AC21: 1 | AD21: 1 | AE21: 1 | AF21: 1 | AG21: 1 | AH21: 1 | AI21: ?
A23: Atribut | C23: A1 | D23: A2 | E23: A3 | F23: A4 | G23: A5 | H23: A6 | I23: A7 | J23: A8 | K23: A9 | L23: A10 | M23: A11 | N23: A12 | O23: A13 | P23: A14 | Q23: A15 | R23: A16 | S23: A17 | T23: A18 | U23: A19 | V23: A20 | W23: A21 | X23: A22 | Y23: A23 | Z23: A24 | AA23: A25 | AB23: A26 | AC23: A27 | AD23: A28 | AE23: A29 | AF23: A30 | AG23: A31 | AH23: A32 | AI23: A33
A24: Yes | C24: =COUNTIFS(B$4:B$9,"0,5",$AI$4:$AI$9,"Yes") -> 0 | D24: =COUNTIFS(C$4:C$9,"0,2",$AI$4:$AI$9,"Yes") -> 1 | E24: =COUNTIFS(D$4:D$9,"0,3",$AI$4:$AI$9,"Yes") -> 1 | F24: =COUNTIFS(E$4:E$9,"0,3",$AI$4:$AI$9,"Yes") -> 0 | G24: =COUNTIFS(F$4:F$9,"0,3",$AI$4:$AI$9,"Yes") -> 1 | H24: =COUNTIFS(G$4:G$9,"1",$AI$4:$AI$9,"Yes") -> 1 | I24: =COUNTIFS(H$4:H$9,"0,5",$AI$4:$AI$9,"Yes") -> 1 | J24: =COUNTIFS(I$4:I$9,"1",$AI$4:$AI$9,"Yes") -> 1 | K24: =COUNTIFS(J$4:J$9,"0,2",$AI$4:$AI$9,"Yes") -> 1 | L24: =COUNTIFS(K$4:K$9,"0",$AI$4:$AI$9,"Yes") -> 1 | M24: =COUNTIFS(L$4:L$9,"0,0",$AI$4:$AI$9,"Yes") -> 1 | N24: =COUNTIFS(M$4:M$9,"0,2",$AI$4:$AI$9,"Yes") -> 1 | O24: =COUNTIFS(N$4:N$9,"0,5",$AI$4:$AI$9,"Yes") -> 1 | P24: =COUNTIFS(O$4:O$9,"0",$AI$4:$AI$9,"Yes") -> 1 | Q24: =COUNTIFS(P$4:P$9,"0",$AI$4:$AI$9,"Yes") -> 1 | R24: =COUNTIFS(Q$4:Q$9,"0",$AI$4:$AI$9,"Yes") -> 1 | S24: =COUNTIFS(R$4:R$9,"1,0",$AI$4:$AI$9,"Yes") -> 1 | T24: =COUNTIFS(S$4:S$9,"0",$AI$4:$AI$9,"Yes") -> 1 | U24: =COUNTIFS(T$4:T$9,"1,0",$AI$4:$AI$9,"Yes") -> 1 | V24: =COUNTIFS(U$4:U$9,"1",$AI$4:$AI$9,"Yes") -> 1 | W24: =COUNTIFS(V$4:V$9,"1",$AI$4:$AI$9,"Yes") -> 1 | X24: =COUNTIFS(W$4:W$9,"0",$AI$4:$AI$9,"Yes") -> 1 | Y24: =COUNTIFS(X$4:X$9,"1",$AI$4:$AI$9,"Yes") -> 1 | Z24: =COUNTIFS(Y$4:Y$9,"1",$AI$4:$AI$9,"Yes") -> 1 | AA24: =COUNTIFS(Z$4:Z$9,"1",$AI$4:$AI$9,"Yes") -> 1 | AB24: =COUNTIFS(AA$4:AA$9,"0",$AI$4:$AI$9,"Yes") -> 1 | AC24: =COUNTIFS(AB$4:AB$9,"1",$AI$4:$AI$9,"Yes") -> 1 | AD24: =COUNTIFS(AC$4:AC$9,"1",$AI$4:$AI$9,"Yes") -> 1 | AE24: =COUNTIFS(AD$4:AD$9,"1",$AI$4:$AI$9,"Yes") -> 1 | AF24: =COUNTIFS(AE$4:AE$9,"1",$AI$4:$AI$9,"Yes") -> 1 | AG24: =COUNTIFS(AF$4:AF$9,"1",$AI$4:$AI$9,"Yes") -> 1 | AH24: =COUNTIFS(AG$4:AG$9,"1",$AI$4:$AI$9,"Yes") -> 1 | AI24: =COUNTIFS(AH$4:AH$9,"1",$AI$4:$AI$9,"Yes") -> 0
A25: No | C25: =COUNTIFS(B$4:B$9,"0,5",$AI$4:$AI$9,"No") -> 1 | D25: =COUNTIFS(C$4:C$9,"0,2",$AI$4:$AI$9,"No") -> 0 | E25: =COUNTIFS(D$4:D$9,"0,3",$AI$4:$AI$9,"No") -> 0 | F25: =COUNTIFS(E$4:E$9,"0,7",$AI$4:$AI$9,"NO") -> 0 | G25: =COUNTIFS(F$4:F$9,"0,3",$AI$4:$AI$9,"No") -> 0 | H25: =COUNTIFS(G$4:G$9,"1,0",$AI$4:$AI$9,"No") -> 0 | I25: =COUNTIFS(H$4:H$9,"0,5",$AI$4:$AI$9,"No") -> 0 | J25: =COUNTIFS(I$4:I$9,"1",$AI$4:$AI$9,"No") -> 0 | K25: =COUNTIFS(J$4:J$9,"0,2",$AI$4:$AI$9,"No") -> 0 | L25: =COUNTIFS(K$4:K$9,"0",$AI$4:$AI$9,"No") -> 0 | M25: =COUNTIFS(L$4:L$9,"0,0",$AI$4:$AI$9,"No") -> 0 | N25: =COUNTIFS(M$4:M$9,"0,2",$AI$4:$AI$9,"No") -> 0 | O25: =COUNTIFS(N$4:N$9,"0,5",$AI$4:$AI$9,"No") -> 0 | P25: =COUNTIFS(O$4:O$9,"0,0",$AI$4:$AI$9,"No") -> 0 | Q25: =COUNTIFS(P$4:P$9,"0",$AI$4:$AI$9,"No") -> 0 | R25: =COUNTIFS(Q$4:Q$9,"0",$AI$4:$AI$9,"No") -> 0 | S25: =COUNTIFS(R$4:R$9,"1,0",$AI$4:$AI$9,"No") -> 0 | T25: =COUNTIFS(S$4:S$9,"0",$AI$4:$AI$9,"No") -> 0 | U25: =COUNTIFS(T$4:T$9,"1,0",$AI$4:$AI$9,"No") -> 0 | V25: =COUNTIFS(T$4:T$9,"1,0",$AI$4:$AI$9,"No") -> 0 | W25: =COUNTIFS(V$4:V$9,"1",$AI$4:$AI$9,"No") -> 5 | X25: =COUNTIFS(W$4:W$9,"0,0",$AI$4:$AI$9,"No") -> 0 | Y25: =COUNTIFS(X$4:X$9,"1",$AI$4:$AI$9,"No") -> 0 | Z25: =COUNTIFS(Y$4:Y$9,"1",$AI$4:$AI$9,"No") -> 0 | AA25: =COUNTIFS(Z$4:Z$9,"1",$AI$4:$AI$9,"No") -> 0 | AB25: =COUNTIFS(AA$4:AA$9,"0",$AI$4:$AI$9,"No") -> 0 | AC25: =COUNTIFS(AB$4:AB$9,"1",$AI$4:$AI$9,"No") -> 0 | AD25: =COUNTIFS(AC$4:AC$9,"1",$AI$4:$AI$9,"No") -> 5 | AE25: =COUNTIFS(AD$4:AD$9,"1",$AI$4:$AI$9,"No") -> 0 | AF25: =COUNTIFS(AE$4:AE$9,"1",$AI$4:$AI$9,"No") -> 5 | AG25: =COUNTIFS(AF$4:AF$9,"1",$AI$4:$AI$9,"No") -> 0 | AH25: =COUNTIFS(AG$4:AG$9,"1",$AI$4:$AI$9,"No") -> 5 | AI25: =COUNTIFS(AH$4:AH$9,"1",$AI$4:$AI$9,"No") -> 0
A26: P(X|CI) | B26: Yes | C26: =C24/$B$17 -> 0 | D26: =D24/$B$17 -> 1 | E26: =E24/$B$17 -> 1 | F26: =F24/$B$17 -> 0 | G26: =G24/$B$17 -> 1 | H26: =H24/$B$17 -> 1 | I26: =I24/$B$17 -> 1 | J26: =J24/$B$17 -> 1 | ... AI26: =AI24/$B$17 -> 0 | AJ26: =C26*D26*E26*F26*G26*H26*I26*J26*K26*L26*M26*N26*O26*P26*Q26*R26*S26*T26*U26*V26*W26*X26*Y26*Z26*AA26*AB26*AC26*AD26*AE26*AF26*AG26*AH26*AI26 -> 0
B27: No | C27: =C25/$C$17 -> 0.2 | D27: =D25/$C$17 -> 0 | E27: =E25/$C$17 -> 0 | F27: =F25/$C$17 -> 0 | G27: =G25/$C$17 -> 0 | H27: =H25/$C$17 -> 0 | I27: =I25/$C$17 -> 0 | J27: =J25/$C$17 -> 0 | ... AI27: =AI25/$C$17 -> 0 | AJ27: =C27*D27*E27*F27*G27*H27*I27*J27*K27*L27*M27*N27*O27*P27*Q27*R27*S27*T27*U27*V27*W27*X27*Y27*Z27*AA27*AB27*AC27*AD27*AE27*AF27*AG27*AH27*AI27 -> 0
A29: (P(X|H) * P(H)) / P(X) | C29: NEW KELAS
A30: Yes | B30: =AJ26*$B$18 -> 0 | C30: =IF(B30>B31,A30, A31) -> No
A31: No | B31: =AJ27*$C$18 -> 0
B33: A1 | C33: A2 | D33: A3 | E33: A4 | F33: A5 | G33: A6 | H33: A7 | I33: A8 | J33: A9 | K33: A10 | L33: A11 | M33: A12 | N33: A13 | O33: A14 | P33: A15 | Q33: A16 | R33: A17 | S33: A18 | T33: A19 | U33: A20 | V33: A21 | W33: A22 | X33: A23 | Y33: A24 | Z33: A25 | AA33: A26 | AB33: A27 | AC33: A28 | AD33: A29 | AE33: A30 | AF33: A31 | AG33: A32 | AH33: A33
A34: D8 | B34: 0 | C34: 0.1 | D34: 0.2 | E34: 0.5 | F34: 0.1 | G34: 0.9 | H34: 0.55416667 | I34: 0.84810127 | J34: 0.42278481 | K34: 0.13055556 | L34: 0.05 | M34: 0.26216216 | N34: 0.515625 | O34: 0.075 | P34: 0.050632911 | Q34: 0.1 | R34: 0.9382716 | S34: 0.38271605 | T34: 0.96296296 | U34: 1 | V34: 1 | W34: 0.12345679 | X34: 0.96296296 | Y34: 0.95061728 | Z34: 0.75308642 | AA34: 0.35802469 | AB34: 0.98765432 | AC34: 1 | AD34: 0.97530864 | AE34: 1 | AF34: 0.4625 | AG34: 1 | AH34: 0.8961039 | AI34: ?
A36: Atribut | C36: A1 | D36: A2 | E36: A3 | F36: A4 | G36: A5 | H36: A6 | I36: A7 | J36: A8 | K36: A9 | L36: A10 | M36: A11 | N36: A12 | O36: A13 | P36: A14 | Q36: A15 | R36: A16 | S36: A17 | T36: A18 | U36: A19 | V36: A20 | W36: A21 | X36: A22 | Y36: A23 | Z36: A24 | AA36: A25 | AB36: A26 | AC36: A27 | AD36: A28 | AE36: A29 | AF36: A30 | AG36: A31 | AH36: A32 | AI36: A33
A37: Yes | C37: =COUNTIFS(B$4:B$9,"0,0",$AI$4:$AI$9,"Yes") -> 0 | D37: =COUNTIFS(C$4:C$9,"0,1",$AI$4:$AI$9,"Yes") -> 0 | E37: =COUNTIFS(D$4:D$9,"0,2",$AI$4:$AI$9,"Yes") -> 0 | F37: =COUNTIFS(E$4:E$9,"0,5",$AI$4:$AI$9,"Yes") -> 0 | G37: =COUNTIFS(F$4:F$9,"0,1",$AI$4:$AI$9,"Yes") -> 0 | H37: =COUNTIFS(G$4:G$9,"0,9",$AI$4:$AI$9,"Yes") -> 0 | I37: =COUNTIFS(H$4:H$9,"0,6",$AI$4:$AI$9,"Yes") -> 0 | J37: =COUNTIFS(I$4:I$9,"0,8",$AI$4:$AI$9,"Yes") -> 0 | K37: =COUNTIFS(J$4:J$9,"0,4",$AI$4:$AI$9,"Yes") -> 0 | L37: =COUNTIFS(K$4:K$9,"0,1",$AI$4:$AI$9,"Yes") -> 0 | M37: =COUNTIFS(L$4:L$9,"0,1",$AI$4:$AI$9,"Yes") -> 0 | N37: =COUNTIFS(M$4:M$9,"0,3",$AI$4:$AI$9,"Yes") -> 0 | O37: =COUNTIFS(N$4:N$9,"0,5",$AI$4:$AI$9,"Yes") -> 1 | P37: =COUNTIFS(O$4:O$9,"0,1",$AI$4:$AI$9,"Yes") -> 0 | Q37: =COUNTIFS(P$4:P$9,"0,1",$AI$4:$AI$9,"Yes") -> 0 | R37: =COUNTIFS(Q$4:Q$9,"0,1",$AI$4:$AI$9,"Yes") -> 0 | S37: =COUNTIFS(R$4:R$9,"0,9",$AI$4:$AI$9,"Yes") -> 0 | T37: =COUNTIFS(S$4:S$9,"0,4",$AI$4:$AI$9,"Yes") -> 0 | U37: =COUNTIFS(T$4:T$9,"1,0",$AI$4:$AI$9,"Yes") -> 1 | V37: =COUNTIFS(U$4:U$9,"1,0",$AI$4:$AI$9,"Yes") -> 1 | W37: =COUNTIFS(V$4:V$9,"1,0",$AI$4:$AI$9,"Yes") -> 1 | X37: =COUNTIFS(W$4:W$9,"0,1",$AI$4:$AI$9,"Yes") -> 0 | Y37: =COUNTIFS(X$4:X$9,"1,0",$AI$4:$AI$9,"Yes") -> 1 | Z37: =COUNTIFS(Y$4:Y$9,"1,0",$AI$4:$AI$9,"Yes") -> 1 | AA37: =COUNTIFS(Z$4:Z$9,"0,8",$AI$4:$AI$9,"Yes") -> 0 | AB37: =COUNTIFS(AA$4:AA$9,"0,4",$AI$4:$AI$9,"Yes") -> 0 | AC37: =COUNTIFS(AB$4:AB$9,"1,0",$AI$4:$AI$9,"Yes") -> 1 | AD37: =COUNTIFS(AC$4:AC$9,"1,0",$AI$4:$AI$9,"Yes") -> 1 | AE37: =COUNTIFS(AD$4:AD$9,"1,0",$AI$4:$AI$9,"Yes") -> 1 | AF37: =COUNTIFS(AE$4:AE$9,"1,0",$AI$4:$AI$9,"Yes") -> 1 | AG37: =COUNTIFS(AF$4:AF$9,"0,5",$AI$4:$AI$9,"Yes") -> 0 | AH37: =COUNTIFS(AG$4:AG$9,"1,0",$AI$4:$AI$9,"Yes") -> 1 | AI37: =COUNTIFS(AH$4:AH$9,"0,9",$AI$4:$AI$9,"Yes") -> 0
A38: No | C38: =COUNTIFS(B$4:B$9,"0,0",$AI$4:$AI$9,"No") -> 4 | D38: =COUNTIFS(C$4:C$9,"0,1",$AI$4:$AI$9,"No") -> 5 | E38: =COUNTIFS(D$4:D$9,"0,2",$AI$4:$AI$9,"No") -> 5 | F38: =COUNTIFS(E$4:E$9,"0,5",$AI$4:$AI$9,"No") -> 5 | G38: =COUNTIFS(F$4:F$9,"0,1",$AI$4:$AI$9,"No") -> 5 | H38: =COUNTIFS(G$4:G$9,"0,9",$AI$4:$AI$9,"No") -> 5 | I38: =COUNTIFS(H$4:H$9,"0,6",$AI$4:$AI$9,"No") -> 0 | J38: =COUNTIFS(I$4:I$9,"0,8",$AI$4:$AI$9,"No") -> 0 | K38: =COUNTIFS(J$4:J$9,"0,4",$AI$4:$AI$9,"No") -> 0 | L38: =COUNTIFS(K$4:K$9,"0,1",$AI$4:$AI$9,"No") -> 0 | M38: =COUNTIFS(L$4:L$9,"0,1",$AI$4:$AI$9,"No") -> 0 | N38: =COUNTIFS(M$4:M$9,"0,3",$AI$4:$AI$9,"No") -> 0 | O38: =COUNTIFS(N$4:N$9,"0,5",$AI$4:$AI$9,"No") -> 0 | P38: =COUNTIFS(O$4:O$9,"0,1",$AI$4:$AI$9,"No") -> 0 | Q38: =COUNTIFS(P$4:P$9,"0,1",$AI$4:$AI$9,"No") -> 0 | R38: =COUNTIFS(Q$4:Q$9,"0,1",$AI$4:$AI$9,"No") -> 0 | S38: =COUNTIFS(R$4:R$9,"0,9",$AI$4:$AI$9,"No") -> 0 | T38: =COUNTIFS(S$4:S$9,"0,4",$AI$4:$AI$9,"No") -> 0 | U38: =COUNTIFS(T$4:T$9,"1,0",$AI$4:$AI$9,"No") -> 0 | V38: =COUNTIFS(U$4:U$9,"1,0",$AI$4:$AI$9,"No") -> 5 | W38: =COUNTIFS(V$4:V$9,"1,0",$AI$4:$AI$9,"No") -> 5 | X38: =COUNTIFS(W$4:W$9,"0,1",$AI$4:$AI$9,"No") -> 0 | Y38: =COUNTIFS(X$4:X$9,"1,0",$AI$4:$AI$9,"No") -> 0 | Z38: =COUNTIFS(Y$4:Y$9,"1,0",$AI$4:$AI$9,"No") -> 0 | AA38: =COUNTIFS(Z$4:Z$9,"0,8",$AI$4:$AI$9,"No") -> 0 | AB38: =COUNTIFS(AA$4:AA$9,"0,4",$AI$4:$AI$9,"No") -> 0 | AC38: =COUNTIFS(AB$4:AB$9,"1,0",$AI$4:$AI$9,"No") -> 0 | AD38: =COUNTIFS(AC$4:AC$9,"1,0",$AI$4:$AI$9,"No") -> 5 | AE38: =COUNTIFS(AD$4:AD$9,"1,0",$AI$4:$AI$9,"No") -> 0 | AF38: =COUNTIFS(AE$4:AE$9,"1,0",$AI$4:$AI$9,"No") -> 5 | AG38: =COUNTIFS(AF$4:AF$9,"0,5",$AI$4:$AI$9,"No") -> 0 | AH38: =COUNTIFS(AG$4:AG$9,"1,0",$AI$4:$AI$9,"No") -> 5 | AI38: =COUNTIFS(AH$4:AH$9,"0,9",$AI$4:$AI$9,"No") -> 0
A39: P(X|CI) | B39: Yes | C39: =C37/$B$17 -> 0 | D39: =D37/$B$17 -> 0 | E39: =E37/$B$17 -> 0 | F39: =F37/$B$17 -> 0 | G39: =G37/$B$17 -> 0 | H39: =H37/$B$17 -> 0 | I39: =I37/$B$17 -> 0 | J39: =J37/$B$17 -> 0 | ... AI39: =AI37/$B$17 -> 0 | AJ39: =C39*D39*E39*F39*G39*H39*I39*J39*K39*L39*M39*N39*O39*P39*Q39*R39*S39*T39*U39*V39*W39*X39*Y39*Z39*AA39*AB39*AC39*AD39*AE39*AF39*AG39*AH39*AI39 -> 0
B40: No | C40: =C38/$C$17 -> 0.8 | D40: =D38/$C$17 -> 1 | E40: =E38/$C$17 -> 1 | F40: =F38/$C$17 -> 1 | G40: =G38/$C$17 -> 1 | H40: =H38/$C$17 -> 1 | I40: =I38/$C$17 -> 0 | J40: =J38/$C$17 -> 0 | ... AI40: =AI38/$C$17 -> 0 | AJ40: =C40*D40*E40*F40*G40*H40*I40*J40*K40*L40*M40*N40*O40*P40*Q40*R40*S40*T40*U40*V40*W40*X40*Y40*Z40*AA40*AB40*AC40*AD40*AE40*AF40*AG40*AH40*AI40 -> 0
A42: (P(X|H) * P(H)) / P(X) | C42: NEW KELAS
A43: Yes | B43: =AJ39*$B$18 -> 0 | C43: =IF(B43>B44,A43, A44) -> No
A44: No | B44: =AJ40*$C$18 -> 0
B46: A1 | C46: A2 | D46: A3 | E46: A4 | F46: A5 | G46: A6 | H46: A7 | I46: A8 | J46: A9 | K46: A10 | L46: A11 | M46: A12 | N46: A13 | O46: A14 | P46: A15 | Q46: A16 | R46: A17 | S46: A18 | T46: A19 | U46: A20 | V46: A21 | W46: A22 | X46: A23 | Y46: A24 | Z46: A25 | AA46: A26 | AB46: A27 | AC46: A28 | AD46: A29 | AE46: A30 | AF46: A31 | AG46: A32 | AH46: A33
A47: D9 | B47: 0.2 | C47: 0 | D47: 0 | E47: 0 | F47: 0 | G47: 1 | H47: 0.5 | I47: 1 | J47: 0.4 | K47: 1 | L47: 0 | M47: 0 | N47: 0.5 | O47: 0 | P47: 0 | Q47: 0 | R47: 1 | S47: 1 | T47: 1 | U47: 1 | V47: 1 | W47: 1 | X47: 1 | Y47: 1 | Z47: 0 | AA47: 1 | AB47: 1 | AC47: 1 | AD47: 1 | AE47: 1 | AF47: 0 | AG47: 1 | AH47: 1 | AI47: ?
A49: Atribut | C49: A1 | D49: A2 | E49: A3 | F49: A4 | G49: A5 | H49: A6 | I49: A7 | J49: A8 | K49: A9 | L49: A10 | M49: A11 | N49: A12 | O49: A13 | P49: A14 | Q49: A15 | R49: A16 | S49: A17 | T49: A18 | U49: A19 | V49: A20 | W49: A21 | X49: A22 | Y49: A23 | Z49: A24 | AA49: A25 | AB49: A26 | AC49: A27 | AD49: A28 | AE49: A29 | AF49: A30 | AG49: A31 | AH49: A32 | AI49: A33
A50: Yes | C50: =COUNTIFS(B$4:B$9,"0,2",$AI$4:$AI$9,"Yes") -> 0 | D50: =COUNTIFS(C$4:C$9,"0,0",$AI$4:$AI$9,"Yes") -> 0 | E50: =COUNTIFS(D$4:D$9,"0,0",$AI$4:$AI$9,"Yes") -> 0 | F50: =COUNTIFS(E$4:E$9,"0,0",$AI$4:$AI$9,"Yes") -> 0 | G50: =COUNTIFS(F$4:F$9,"0,0",$AI$4:$AI$9,"Yes") -> 0 | H50: =COUNTIFS(G$4:G$9,"1,0",$AI$4:$AI$9,"Yes") -> 1 | I50: =COUNTIFS(H$4:H$9,"0,5",$AI$4:$AI$9,"Yes") -> 1 | J50: =COUNTIFS(I$4:I$9,"1,0",$AI$4:$AI$9,"Yes") -> 1 | K50: =COUNTIFS(J$4:J$9,"0,4",$AI$4:$AI$9,"Yes") -> 0 | L50: =COUNTIFS(K$4:K$9,"1,0",$AI$4:$AI$9,"Yes") -> 0 | M50: =COUNTIFS(L$4:L$9,"0,0",$AI$4:$AI$9,"Yes") -> 1 | N50: =COUNTIFS(M$4:M$9,"0,0",$AI$4:$AI$9,"Yes") -> 0 | O50: =COUNTIFS(N$4:N$9,"0,5",$AI$4:$AI$9,"Yes") -> 1 | P50: =COUNTIFS(O$4:O$9,"0,0",$AI$4:$AI$9,"Yes") -> 1 | Q50: =COUNTIFS(P$4:P$9,"0,0",$AI$4:$AI$9,"Yes") -> 1 | R50: =COUNTIFS(Q$4:Q$9,"0,0",$AI$4:$AI$9,"Yes") -> 1 | S50: =COUNTIFS(R$4:R$9,"1,0",$AI$4:$AI$9,"Yes") -> 1 | T50: =COUNTIFS(S$4:S$9,"1,0",$AI$4:$AI$9,"Yes") -> 0 | U50: =COUNTIFS(T$4:T$9,"1,0",$AI$4:$AI$9,"Yes") -> 1 | V50: =COUNTIFS(U$4:U$9,"1,0",$AI$4:$AI$9,"Yes") -> 1 | W50: =COUNTIFS(V$4:V$9,"1,0",$AI$4:$AI$9,"Yes") -> 1 | X50: =COUNTIFS(W$4:W$9,"1,0",$AI$4:$AI$9,"Yes") -> 0 | Y50: =COUNTIFS(X$4:X$9,"1,0",$AI$4:$AI$9,"Yes") -> 1 | Z50: =COUNTIFS(Y$4:Y$9,"1,0",$AI$4:$AI$9,"Yes") -> 1 | AA50: =COUNTIFS(Z$4:Z$9,"0,0",$AI$4:$AI$9,"Yes") -> 0 | AB50: =COUNTIFS(AA$4:AA$9,"1,0",$AI$4:$AI$9,"Yes") -> 0 | AC50: =COUNTIFS(AB$4:AB$9,"1,0",$AI$4:$AI$9,"Yes") -> 1 | AD50: =COUNTIFS(AC$4:AC$9,"1,0",$AI$4:$AI$9,"Yes") -> 1 | AE50: =COUNTIFS(AD$4:AD$9,"1,0",$AI$4:$AI$9,"Yes") -> 1 | AF50: =COUNTIFS(AE$4:AE$9,"1,0",$AI$4:$AI$9,"Yes") -> 1 | AG50: =COUNTIFS(AF$4:AF$9,"0,0",$AI$4:$AI$9,"Yes") -> 0 | AH50: =COUNTIFS(AG$4:AG$9,"1,0",$AI$4:$AI$9,"Yes") -> 1 | AI50: =COUNTIFS(AH$4:AH$9,"1,0",$AI$4:$AI$9,"Yes") -> 0
A51: No | C51: =COUNTIFS(B$4:B$9,"0,2",$AI$4:$AI$9,"No") -> 0 | D51: =COUNTIFS(C$4:C$9,"0,0",$AI$4:$AI$9,"No") -> 0 | E51: =COUNTIFS(D$4:D$9,"0,0",$AI$4:$AI$9,"No") -> 0 | F51: =COUNTIFS(E$4:E$9,"0,0",$AI$4:$AI$9,"No") -> 0 | G51: =COUNTIFS(F$4:F$9,"0,0",$AI$4:$AI$9,"No") -> 0 | H51: =COUNTIFS(G$4:G$9,"1,0",$AI$4:$AI$9,"No") -> 0 | I51: =COUNTIFS(H$4:H$9,"0,5",$AI$4:$AI$9,"No") -> 0 | J51: =COUNTIFS(I$4:I$9,"1,0",$AI$4:$AI$9,"No") -> 0 | K51: =COUNTIFS(J$4:J$9,"0,4",$AI$4:$AI$9,"No") -> 0 | L51: =COUNTIFS(K$4:K$9,"1,0",$AI$4:$AI$9,"No") -> 0 | M51: =COUNTIFS(L$4:L$9,"0,0",$AI$4:$AI$9,"No") -> 0 | N51: =COUNTIFS(M$4:M$9,"0,0",$AI$4:$AI$9,"No") -> 0 | O51: =COUNTIFS(N$4:N$9,"0,5",$AI$4:$AI$9,"No") -> 0 | P51: =COUNTIFS(O$4:O$9,"0,0",$AI$4:$AI$9,"No") -> 0 | Q51: =COUNTIFS(P$4:P$9,"0,0",$AI$4:$AI$9,"No") -> 0 | R51: =COUNTIFS(Q$4:Q$9,"0,0",$AI$4:$AI$9,"No") -> 0 | S51: =COUNTIFS(R$4:R$9,"1,0",$AI$4:$AI$9,"No") -> 0 | T51: =COUNTIFS(S$4:S$9,"1,0",$AI$4:$AI$9,"No") -> 0 | U51: =COUNTIFS(T$4:T$9,"1,0",$AI$4:$AI$9,"No") -> 0 | V51: =COUNTIFS(U$4:U$9,"1,0",$AI$4:$AI$9,"No") -> 5 | W51: =COUNTIFS(V$4:V$9,"1,0",$AI$4:$AI$9,"No") -> 5 | X51: =COUNTIFS(W$4:W$9,"1,0",$AI$4:$AI$9,"No") -> 0 | Y51: =COUNTIFS(X$4:X$9,"1,0",$AI$4:$AI$9,"No") -> 0 | Z51: =COUNTIFS(Y$4:Y$9,"1,0",$AI$4:$AI$9,"No") -> 0 | AA51: =COUNTIFS(Z$4:Z$9,"0,0",$AI$4:$AI$9,"No") -> 0 | AB51: =COUNTIFS(AA$4:AA$9,"1,0",$AI$4:$AI$9,"No") -> 0 | AC51: =COUNTIFS(AB$4:AB$9,"1,0",$AI$4:$AI$9,"No") -> 0 | AD51: =COUNTIFS(AC$4:AC$9,"1,0",$AI$4:$AI$9,"No") -> 5 | AE51: =COUNTIFS(AD$4:AD$9,"1,0",$AI$4:$AI$9,"No") -> 0 | AF51: =COUNTIFS(AE$4:AE$9,"1,0",$AI$4:$AI$9,"No") -> 5 | AG51: =COUNTIFS(AF$4:AF$9,"0,0",$AI$4:$AI$9,"No") -> 0 | AH51: =COUNTIFS(AG$4:AG$9,"1,0",$AI$4:$AI$9,"No") -> 5 | AI51: =COUNTIFS(AH$4:AH$9,"1,0",$AI$4:$AI$9,"No") -> 0
...

Sheet C4.5
A1: No | B1: Atribut | D1: Sum Kasus | E1: Yes | F1: No | G1: Entropy | H1: Information Gain | I1: Split Info | J1: Gain Ratio
B2: Node 1 | C2: Kategori | D2: 10 | E2: =COUNTIF(NORMALISASI!A2:A11,"YES") -> 2 | F2: =COUNTIF(NORMALISASI!A2:A11,"NO") -> 8 | G2: =((-E2/D2)*IMLOG2(E2/D2)+(-F2/D2)*IMLOG2(F2/D2)) -> 0.72192809
A3: 1 | B3: Anggota ART | H3: =M9 -> 0 | I3: =-((D4/D2*(IMLOG2(D4/D2)))+(D5/D2*(IMLOG2(D5/D2)))+(D7/D2*(IMLOG2(D7/D2)))+(D8/D2*(IMLOG2(D8/D2)))) -> 1.6854753 | J3: =H3/I3 -> 0
C4: 1 | D4: =COUNTIF(CLEANING!C2:C11,"1") -> 5 | E4: =COUNTIFS(CLEANING!C2:C11,"1",CLEANING!B2:B11,"YES") -> 0 | F4: =COUNTIFS(CLEANING!C2:C11,"1",CLEANING!B2:B11,"No") -> 5
C5: 2 | D5: =COUNTIF(CLEANING!C2:C11,"2") -> 1 | E5: =COUNTIFS(CLEANING!C2:C11,"2",CLEANING!B2:B11,"YES") -> 0 | F5: =COUNTIFS(CLEANING!C2:C11,"2",CLEANING!B2:B11,"No") -> 1
C6: 3 | D6: =COUNTIF(CLEANING!C2:C11,"3") -> 0 | E6: =COUNTIFS(CLEANING!C2:C11,"3",CLEANING!B2:B11,"YES") -> 0 | F6: =COUNTIFS(CLEANING!C2:C11,"3",CLEANING!B2:B11,"No") -> 0
C7: 4 | D7: =COUNTIF(CLEANING!C2:C11,"4") -> 3 | E7: =COUNTIFS(CLEANING!C2:C11,"4",CLEANING!B2:B11,"YES") -> 1 | F7: =COUNTIFS(CLEANING!C2:C11,"4",CLEANING!B2:B11,"No") -> 2 | G7: =((-E7/D7)*IMLOG2(E7/D7)+(-F7/D7)*IMLOG2(F7/D7)) -> 0.91829583
C8: 5 | D8: =COUNTIF(CLEANING!C2:C11,"5") -> 1 | E8: =COUNTIFS(CLEANING!C2:C11,"5",CLEANING!B2:B11,"YES") -> 1 | F8: =COUNTIFS(CLEANING!C2:C11,"5",CLEANING!B2:B11,"No") -> 0
A9: 2 | B9: Status bangunan | H9: =(G2)-((D10/D2)*G10)-((D11/D2)*G11) -> 0.08707654 | I9: =-((D10/D2*(IMLOG2(D10/D2)))+(D11/D2*(IMLOG2(D11/D2)))) -> 0.72192809 | J9: =H9/I9 -> 0.12061664
C10: 1 | D10: =COUNTIF(CLEANING!D2:D11,"1") -> 2 | E10: =COUNTIFS(CLEANING!D2:D11,"1",CLEANING!B2:B11,"YES") -> 1 | F10: =COUNTIFS(CLEANING!D2:D11,"1",CLEANING!B2:B11,"No") -> 1 | G10: =((-E10/D10)*IMLOG2(E10/D10)+(-F10/D10)*IMLOG2(F10/D10)) -> 1
C11: 2 | D11: 8 | E11: =COUNTIFS(CLEANING!D2:D11,"2",CLEANING!B2:B11,"YES") -> 1 | F11: 7 | G11: =((-E11/D11)*IMLOG2(E11/D11)+(-F11/D11)*IMLOG2(F11/D11)) -> 0.54356444
C12: 3 | D12: =COUNTIF(CLEANING!D2:D11,"3") -> 0 | E12: =COUNTIFS(CLEANING!D2:D11,"3",CLEANING!B2:B11,"YES") -> 0 | F12: =COUNTIFS(CLEANING!D2:D11,"3",CLEANING!B2:B11,"No") -> 0
C13: 4 | D13: =COUNTIF(CLEANING!D2:D11,"4") -> 0 | E13: =COUNTIFS(CLEANING!D2:D11,"4",CLEANING!B2:B11,"YES") -> 0 | F13: =COUNTIFS(CLEANING!D2:D11,"4",CLEANING!B2:B11,"No") -> 0
C14: 5 | D14: =COUNTIF(CLEANING!D2:D11,"5") -> 0 | E14: =COUNTIFS(CLEANING!D2:D11,"5",CLEANING!B2:B11,"YES") -> 0 | F14: =COUNTIFS(CLEANING!D2:D11,"5",CLEANING!B2:B11,"No") -> 0
A15: 3 | B15: Status lahan | H15: =(G2)-((D16/D2)*G16)-((D17/D2)*G17) -> 0.08707654 | I15: =-((D16/D2*(IMLOG2(D16/D2)))+(D17/D2*(IMLOG2(D17/D2)))) -> 0.72192809 | J15: =H15/I15 -> 0.12061664
C16: 1 | D16: =COUNTIF(CLEANING!E2:E11,"1") -> 2 | E16: =COUNTIFS(CLEANING!E2:E11,"1",CLEANING!B2:B11,"YES") -> 1 | F16: =COUNTIFS(CLEANING!E2:E11,"1",CLEANING!B2:B11,"No") -> 1 | G16: =((-E16/D16)*IMLOG2(E16/D16)+(-F16/D16)*IMLOG2(F16/D16)) -> 1
C17: 2 | D17: 8 | E17: =COUNTIFS(CLEANING!E2:E11,"2",CLEANING!B2:B11,"YES") -> 1 | F17: 7 | G17: =((-E17/D17)*IMLOG2(E17/D17)+(-F17/D17)*IMLOG2(F17/D17)) -> 0.54356444
C18: 3 | D18: =COUNTIF(CLEANING!E2:E11,"3") -> 0 | E18: =COUNTIFS(CLEANING!E2:E11,"3",CLEANING!B2:B11,"YES") -> 0 | F18: =COUNTIFS(CLEANING!E2:E11,"3",CLEANING!B2:B11,"No") -> 0
C19: 4 | D19: =COUNTIF(CLEANING!E2:E11,"4") -> 0 | E19: =COUNTIFS(CLEANING!E2:E11,"4",CLEANING!B2:B11,"YES") -> 0 | F19: =COUNTIFS(CLEANING!E2:E11,"4",CLEANING!B2:B11,"No") -> 0
C20: 5 | D20: =COUNTIF(CLEANING!E2:E11,"5") -> 0 | E20: =COUNTIFS(CLEANING!E2:E11,"5",CLEANING!B2:B11,"YES") -> 0 | F20: =COUNTIFS(CLEANING!E2:E11,"5",CLEANING!B2:B11,"No") -> 0
A21: 4 | B21: Jenis Lantai | H21: =(G2)-((D27/D2)*G27) -> 0.52192809 | I21: =-((D23/D2*(IMLOG2(D23/D2)))+(D26/D2*(IMLOG2(D26/D2)))+(D27/D2*(IMLOG2(D29/D2)))) -> 1.4387578 | J21: =H21/I21 -> 0.362763
C22: 1 | D22: =COUNTIF(CLEANING!F2:F11,"1") -> 0 | E22: =COUNTIFS(CLEANING!F2:F11,"1",CLEANING!B2:B11,"YES") -> 0 | F22: =COUNTIFS(CLEANING!F2:F11,"1",CLEANING!B2:B11,"No") -> 0
C23: 2 | D23: =COUNTIF(CLEANING!F2:F11,"2") -> 1 | E23: =COUNTIFS(CLEANING!F2:F11,"2",CLEANING!B2:B11,"YES") -> 0 | F23: =COUNTIFS(CLEANING!F2:F11,"2",CLEANING!B2:B11,"No") -> 1
C24: 3 | D24: =COUNTIF(CLEANING!F2:F11,"3") -> 0 | E24: =COUNTIFS(CLEANING!F2:F11,"3",CLEANING!B2:B11,"YES") -> 0 | F24: =COUNTIFS(CLEANING!F2:F11,"3",CLEANING!B2:B11,"No") -> 0
C25: 4 | D25: =COUNTIF(CLEANING!F2:F11,"4") -> 0 | E25: =COUNTIFS(CLEANING!F2:F11,"4",CLEANING!B2:B11,"YES") -> 0 | F25: =COUNTIFS(CLEANING!F2:F11,"4",CLEANING!B2:B11,"No") -> 0
C26: 5 | D26: 6 | E26: =COUNTIFS(CLEANING!F2:F11,"5",CLEANING!B2:B11,"YES") -> 0 | F26: 6
C27: 6 | D27: =COUNTIF(CLEANING!F2:F11,"6") -> 2 | E27: =COUNTIFS(CLEANING!F2:F11,"6",CLEANING!B2:B11,"YES") -> 1 | F27: =COUNTIFS(CLEANING!F2:F11,"6",CLEANING!B2:B11,"No") -> 1 | G27: =((-E27/D27)*IMLOG2(E27/D27)+(-F27/D27)*IMLOG2(F27/D27)) -> 1
C28: 7 | D28: =COUNTIF(CLEANING!F2:F11,"7") -> 0 | E28: =COUNTIFS(CLEANING!F2:F11,"7",CLEANING!B2:B11,"YES") -> 0 | F28: =COUNTIFS(CLEANING!F2:F11,"7",CLEANING!B2:B11,"No") -> 0
C29: 8 | D29: =COUNTIF(CLEANING!F2:F11,"8") -> 1 | E29: =COUNTIFS(CLEANING!F2:F11,"8",CLEANING!B2:B11,"YES") -> 1 | F29: =COUNTIFS(CLEANING!F2:F11,"8",CLEANING!B2:B11,"No") -> 0
C30: 9 | D30: =COUNTIF(CLEANING!F2:F11,"9") -> 0 | E30: =COUNTIFS(CLEANING!F2:F11,"9",CLEANING!B2:B11,"YES") -> 0 | F30: =COUNTIFS(CLEANING!F2:F11,"9",CLEANING!B2:B11,"No") -> 0
C31: 10 | D31: =COUNTIF(CLEANING!F2:F11,"10") -> 0 | E31: =COUNTIFS(CLEANING!F2:F11,"10",CLEANING!B2:B11,"YES") -> 0 | F31: =COUNTIFS(CLEANING!F2:F11,"10",CLEANING!B2:B11,"No") -> 0
A32: 5 | B32: Jenis Dinding | H32: =(G2)-((D35/D2)*G35) -> 0.44643934 | I32: =-((D33/D2*(IMLOG2(D33/D2)))+(D34/D2*(IMLOG2(D35/D2)))) -> 1.3743722 | J32: =H32/I32 -> 0.32483148
C33: 1 | D33: =COUNTIF(CLEANING!G2:G11,"1") -> 1 | E33: =COUNTIFS(CLEANING!G2:G11,"1",CLEANING!B2:B11,"YES") -> 0 | F33: =COUNTIFS(CLEANING!G2:G11,"1",CLEANING!B2:B11,"No") -> 1
C34: 2 | D34: 6 | E34: =COUNTIFS(CLEANING!G2:G11,"2",CLEANING!B2:B11,"YES") -> 0 | F34: 6
C35: 3 | D35: =COUNTIF(CLEANING!G2:G11,"3") -> 3 | E35: =COUNTIFS(CLEANING!G2:G11,"3",CLEANING!B2:B11,"YES") -> 2 | F35: =COUNTIFS(CLEANING!G2:G11,"3",CLEANING!B2:B11,"No") -> 1 | G35: =((-E35/D35)*IMLOG2(E35/D35)+(-F35/D35)*IMLOG2(F35/D35)) -> 0.91829583
C36: 4 | D36: =COUNTIF(CLEANING!G2:G11,"4") -> 0 | E36: =COUNTIFS(CLEANING!G2:G11,"4",CLEANING!B2:B11,"YES") -> 0 | F36: =COUNTIFS(CLEANING!G2:G11,"4",CLEANING!B2:B11,"No") -> 0
C37: 5 | D37: =COUNTIF(CLEANING!G2:G11,"5") -> 0 | E37: =COUNTIFS(CLEANING!G2:G11,"5",CLEANING!B2:B11,"YES") -> 0 | F37: =COUNTIFS(CLEANING!G2:G11,"5",CLEANING!B2:B11,"No") -> 0
C38: 6 | D38: =COUNTIF(CLEANING!G2:G11,"6") -> 0 | E38: =COUNTIFS(CLEANING!G2:G11,"6",CLEANING!B2:B11,"YES") -> 0 | F38: =COUNTIFS(CLEANING!G2:G11,"6",CLEANING!B2:B11,"No") -> 0
C39: 7 | D39: =COUNTIF(CLEANING!G2:G11,"7") -> 0 | E39: =COUNTIFS(CLEANING!G2:G11,"7",CLEANING!B2:B11,"YES") -> 0 | F39: =COUNTIFS(CLEANING!G2:G11,"7",CLEANING!B2:B11,"No") -> 0
A40: 6 | B40: Kondisi Dinding
...

Sheet Sheet1
A1: STATUS | B1: A1 | C1: A2 | D1: A3 | E1: A4 | F1: A5 | G1: A6 | H1: A7 | I1: A8 | J1: A9 | K1: A10 | L1: A11 | M1: A12 | N1: A13 | O1: A14 | P1: A15 | Q1: A16 | R1: A17 | S1: A18 | T1: A19 | U1: A20 | V1: A21 | W1: A22 | X1: A23 | Y1: A24 | Z1: A25 | AA1: A26 | AB1: A27 | AC1: A28 | AD1: A29 | AE1: A30 | AF1: A31 | AG1: A32 | AH1: A33
A2: YES | B2: 0.5 | C2: 0 | D2: 0 | E2: 0.7 | F2: 0 | G2: 1 | H2: 0.5 | I2: 1 | J2: 0.6 | K2: 0.3 | L2: 0 | M2: 0.2 | N2: 0.5 | O2: 0 | P2: 0 | Q2: 0 | R2: 1 | S2: 1 | T2: 1 | U2: 1 | V2: 1 | W2: 0 | X2: 1 | Y2: 1 | Z2: 1 | AA2: 0 | AB2: 1 | AC2: 1 | AD2: 1 | AE2: 1 | AF2: 0 | AG2: 1 | AH2: 1
A3: NO | B3: 0.3 | C3: 0.2 | D3: 0.3 | E3: 0 | F3: 0 | G3: 0 | H3: 0.5 | I3: 0 | J3: 0.4 | K3: 0 | L3: 0 | M3: 0.2 | N3: 0.5 | O3: 0 | P3: 0 | Q3: 0 | R3: 1 | S3: 0 | T3: 1 | U3: 1 | V3: 1 | W3: 0 | X3: 1 | Y3: 1 | Z3: 1 | AA3: 0 | AB3: 1 | AC3: 1 | AD3: 1 | AE3: 1 | AF3: 1 | AG3: 1 | AH3: 0.5
A4: NO | B4: 0.7 | C4: 0.2 | D4: 0.2 | E4: 0.7 | F4: 1 | G4: 0.9 | H4: 1 | I4: 0.84810127 | J4: 0.4 | K4: 0.5 | L4: 0.5 | M4: 0.26216216 | N4: 0.5 | O4: 1 | P4: 0.050632911 | Q4: 0.5 | R4: 1 | S4: 1 | T4: 1 | U4: 1 | V4: 1 | W4: 1 | X4: 1 | Y4: 1 | Z4: 1 | AA4: 1 | AB4: 1 | AC4: 1 | AD4: 1 | AE4: 1 | AF4: 1 | AG4: 1 | AH4: 1
A5: NO | B5: 0.5 | C5: 0 | D5: 0 | E5: 1 | F5: 0.3 | G5: 1 | H5: 0.5 | I5: 1 | J5: 0.6 | K5: 1 | L5: 0 | M5: 0 | N5: 1 | O5: 0 | P5: 0 | Q5: 0 | R5: 1 | S5: 1 | T5: 1 | U5: 1 | V5: 1 | W5: 0 | X5: 1 | Y5: 1 | Z5: 0 | AA5: 1 | AB5: 1 | AC5: 1 | AD5: 1 | AE5: 1 | AF5: 0 | AG5: 1 | AH5: 1
A6: YES | B6: 0.7 | C6: 0.2 | D6: 0.3 | E6: 0.7 | F6: 0 | G6: 1 | H6: 0.5 | I6: 1 | J6: 0.2 | K6: 0 | L6: 0 | M6: 0 | N6: 1 | O6: 0 | P6: 0 | Q6: 0 | R6: 1 | S6: 0 | T6: 1 | U6: 1 | V6: 1 | W6: 0 | X6: 1 | Y6: 1 | Z6: 1 | AA6: 0 | AB6: 1 | AC6: 1 | AD6: 1 | AE6: 1 | AF6: 1 | AG6: 1 | AH6: 1
A7: NO | B7: 0.7 | C7: 0.2 | D7: 0.3 | E7: 0.7 | F7: 0 | G7: 1 | H7: 0.5 | I7: 1 | J7: 0.2 | K7: 0 | L7: 0 | M7: 0.2 | N7: 0.2 | O7: 0 | P7: 0 | Q7: 0 | R7: 0 | S7: 0 | T7: 1 | U7: 1 | V7: 1 | W7: 0 | X7: 1 | Y7: 1 | Z7: 0 | AA7: 0 | AB7: 1 | AC7: 1 | AD7: 1 | AE7: 1 | AF7: 1 | AG7: 1 | AH7: 0.5
A8: NO | B8: 0.7 | C8: 0 | D8: 0 | E8: 1 | F8: 0.3 | G8: 1 | H8: 0.5 | I8: 1 | J8: 0.8 | K8: 0 | L8: 0 | M8: 1 | N8: 0.5 | O8: 0 | P8: 0 | Q8: 0 | R8: 1 | S8: 1 | T8: 1 | U8: 1 | V8: 1 | W8: 0 | X8: 1 | Y8: 1 | Z8: 1 | AA8: 1 | AB8: 1 | AC8: 1 | AD8: 1 | AE8: 1 | AF8: 0 | AG8: 1 | AH8: 0.5
A9: NO | B9: 0.9 | C9: 0 | D9: 1 | E9: 1 | F9: 0.3 | G9: 1 | H9: 0.5 | I9: 1 | J9: 0.4 | K9: 0 | L9: 0 | M9: 0.2 | N9: 0.5 | O9: 0 | P9: 0 | Q9: 0 | R9: 1 | S9: 0 | T9: 1 | U9: 1 | V9: 1 | W9: 0 | X9: 1 | Y9: 1 | Z9: 1 | AA9: 0 | AB9: 1 | AC9: 1 | AD9: 1 | AE9: 1 | AF9: 1 | AG9: 1 | AH9: 0.5
A10: NO | B10: 0.2 | C10: 0.1 | D10: 0.2 | E10: 0.5 | F10: 0.1 | G10: 0.9 | H10: 0.55416667 | I10: 0.84810127 | J10: 0.42278481 | K10: 0.13055556 | L10: 0.05 | M10: 0.26216216 | N10: 0.515625 | O10: 0.075 | P10: 0.050632911 | Q10: 0.1 | R10: 0.9382716 | S10: 0.38271605 | T10: 0.96296296 | U10: 1 | V10: 1 | W10: 0.12345679 | X10: 0.96296296 | Y10: 0.95061728 | Z10: 0.75308642 | AA10: 0.35802469 | AB10: 0.98765432 | AC10: 1 | AD10: 0.97530864 | AE10: 1 | AF10: 0.4625 | AG10: 1 | AH10: 0.8961039
A11: YES | B11: 0.3 | C11: 0.1 | D11: 0.2 | E11: 0.5 | F11: 0.1 | G11: 0.9 | H11: 0.55416667 | I11: 0.84810127 | J11: 0.42278481 | K11: 0.13055556 | L11: 0.05 | M11: 0.26216216 | N11: 0.515625 | O11: 0.075 | P11: 0.050632911 | Q11: 0.1 | R11: 0.9382716 | S11: 0.38271605 | T11: 0.96296296 | U11: 1 | V11: 1 | W11: 0.12345679 | X11: 0.96296296 | Y11: 0.95061728 | Z11: 0.75308642 | AA11: 0.35802469 | AB11: 0.98765432 | AC11: 1 | AD11: 0.97530864 | AE11: 1 | AF11: 0.4625 | AG11: 1 | AH11: 0.8961039
A12: YES | B12: 1 | C12: 0 | D12: 0 | E12: 0 | F12: 0 | G12: 1 | H12: 0.5 | I12: 1 | J12: 0.6 | K12: 0 | L12: 0 | M12: 0.2 | N12: 0.5 | O12: 0 | P12: 0 | Q12: 0 | R12: 1 | S12: 0 | T12: 1 | U12: 1 | V12: 1 | W12: 0 | X12: 1 | Y12: 1 | Z12: 1 | AA12: 0 | AB12: 1 | AC12: 1 | AD12: 1 | AE12: 1 | AF12: 0 | AG12: 1 | AH12: 1
A13: NO | B13: 0.5 | C13: 0 | D13: 0 | E13: 0 | F13: 0 | G13: 1 | H13: 0.5 | I13: 1 | J13: 0.6 | K13: 0 | L13: 0 | M13: 0.2 | N13: 0.5 | O13: 0 | P13: 0 | Q13: 0 | R13: 1 | S13: 0 | T13: 1 | U13: 1 | V13: 1 | W13: 0 | X13: 1 | Y13: 1 | Z13: 1 | AA13: 0 | AB13: 1 | AC13: 1 | AD13: 1 | AE13: 1 | AF13: 0 | AG13: 1 | AH13: 1
... A21: YES | B21: 0.3 | C21: 0 | D21: 0 | E21: 0.7 | F21: 0 | G21: 1 | H21: 0.5 | I21: 1 | J21: 0.6 | K21: 0 | L21: 0 | M21: 0.2 | N21: 0.5 | O21: 0 | P21: 0 | Q21: 0 | R21: 1 | S21: 1 | T21: 1 | U21: 1 | V21: 1 | W21: 0 | X21: 1 | Y21: 1 | Z21: 1 | AA21: 1 | AB21: 1 | AC21: 1 | AD21: 1 | AE21: 1 | AF21: 0 | AG21: 1 | AH21: 1
A23: No | B23: Atribut | D23: YES | E23: NO | F23: TOTAL | G23: Entropy | H23: Information Gain
B24: Node 1 | C24: Kategori | D24: 4 | E24: 8 | F24: 12
A25: 1 | B25: Anggota ART
C26: <=0,25 | D26: =COUNTIFS(B2:B13,"<=0,25",A2:A13,"YES") -> 0 | E26: =COUNTIFS(B2:B13,"<=0,25",A2:A13,"NO") -> 1 | F26: =SUM(D26:E26) -> 1 | G26: 0 | H26: =F28-((F26/12)*G26)-((F27/12)*G27) -> 2.8333333
C27: >0,25 | D27: 1 | E27: 1 | F27: =SUM(D27:E27) -> 2 | G27: =((-D27/F27)*IMLOG2(D27/F27)+(-E27/F27)*IMLOG2(E27/F27)) -> 1
D28: =SUM(D26:D27) -> 1 | E28: =SUM(E26:E27) -> 2 | F28: =SUM(D28:E28) -> 3
C29: <=0,5 | D29: 1 | E29: 2 | F29: =SUM(D29:E29) -> 3 | G29: =((-D29/F29)*IMLOG2(D29/F29)+(-E29/F29)*IMLOG2(E29/F29)) -> 0.91829583 | H29: =F31-((F29/12)*G29)-((F30/12)*G30) -> 2.770426
C30: >0,5 | D30: 0 | E30: 0 | F30: =SUM(D30:E30) -> 0 | G30: 0
D31: =SUM(D29:D30) -> 1 | E31: =SUM(E29:E30) -> 2 | F31: =SUM(D31:E31) -> 3
C32: <=0,75 | D32: 1 | E32: 3 | F32: =SUM(D32:E32) -> 4 | G32: =((-D32/F32)*IMLOG2(D32/F32)+(-E32/F32)*IMLOG2(E32/F32)) -> 0.81127812 | H32: =F34-((F32/12)*G32)-((F33/12)*G33) -> 5.5629073
C33: >0,75 | D33: 1 | E33: 1 | F33: =SUM(D33:E33) -> 2 | G33: =((-D33/F33)*IMLOG2(D33/F33)+(-E33/F33)*IMLOG2(E33/F33)) -> 1
D34: =SUM(D32:D33) -> 2 | E34: =SUM(E32:E33) -> 4 | F34: =SUM(D34:E34) -> 6
A35: 2 | B35: Status bangunan
C36: 0 | D36: =COUNTIFS($C$2:$C$13,C36,$A$2:$A$13,$D$23) -> 2 | E36: =COUNTIFS($C$2:$C$13,C36,$A$2:$A$13,$E$23) -> 4 | F36: =SUM(D36:E36) -> 6 | G36: =((-D36/F36)*IMLOG2(D36/F36)+(-E36/F36)*IMLOG2(E36/F36)) -> 0.91829583 | H36: =F39-((F36/12)*G36)-((F37/12)*G37)-((F38/12)*G38) -> 11.103759
C37: 0.1 | D37: =COUNTIFS($C$2:$C$13,C37,$A$2:$A$13,$D$23) -> 1 | E37: =COUNTIFS($C$2:$C$13,C37,$A$2:$A$13,$E$23) -> 1 | F37: =SUM(D37:E37) -> 2 | G37: =((-D37/F37)*IMLOG2(D37/F37)+(-E37/F37)*IMLOG2(E37/F37)) -> 1
C38: 0.2 | D38: =COUNTIFS($C$2:$C$13,C38,$A$2:$A$13,$D$23) -> 1 | E38: =COUNTIFS($C$2:$C$13,C38,$A$2:$A$13,$E$23) -> 3 | F38: =SUM(D38:E38) -> 4 | G38: =((-D38/F38)*IMLOG2(D38/F38)+(-E38/F38)*IMLOG2(E38/F38)) -> 0.81127812
D39: 4 | E39: 8 | F39: 12
A40: 3 | B40: Status lahan
C41: <=0,25 | D41: 3 | E41: 5 | F41: 8 | G41: =((-D41/F41)*IMLOG2(D41/F41)+(-E41/F41)*IMLOG2(E41/F41)) -> 0.954434 | H41: =F43-((F41/12)*G41)-((F42/12)*G42) -> 11.093285
C42: >0,25 | D42: 1 | E42: 3 | F42: 4 | G42: =((-D42/F42)*IMLOG2(D42/F42)+(-E42/F42)*IMLOG2(E42/F42)) -> 0.81127812
D43: 4 | E43: 8 | F43: 12
A44: 4 | B44: Jenis Lantai
C45: <=0,25 | D45: 1 | E45: 2 | F45: 3 | G45: =((-D45/F45)*IMLOG2(D45/F45)+(-E45/F45)*IMLOG2(E45/F45)) -> 0.91829583 | H45: =F47-((F45/12)*G45)-((F46/12)*G46) -> 4.6037594
C46: >0,25 | D46: 1 | E46: 1 | F46: 2 | G46: =((-D46/F46)*IMLOG2(D46/F46)+(-E46/F46)*IMLOG2(E46/F46)) -> 1
D47: 2 | E47: 3 | F47: 5
C48: <=0,75 | D48: 2 | E48: 2 | F48: 4 | G48: =((-D48/F48)*IMLOG2(D48/F48)+(-E48/F48)*IMLOG2(E48/F48)) -> 1 | H48: =F50-((F48/12)*G48)-((F49/12)*G49) -> 6.6666667
...

Sheet Sheet1 (2)
A1: STATUS | B1: A1 | C1: A2 | D1: A3 | E1: A4 | F1: A5 | G1: A6 | H1: A7 | I1: A8 | J1: A9 | K1: A10 | L1: A11 | M1: A12 | N1: A13 | O1: A14 | P1: A15 | Q1: A16 | R1: A17 | S1: A18 | T1: A19 | U1: A20 | V1: A21 | W1: A22 | X1: A23 | Y1: A24 | Z1: A25 | AA1: A26 | AB1: A27 | AC1: A28 | AD1: A29 | AE1: A30 | AF1: A31 | AG1: A32 | AH1: A33
A2: YES | B2: 0.5 | C2: 0 | D2: 0 | E2: 0.7 | F2: 0 | G2: 1 | H2: 0.5 | I2: 1 | J2: 0.6 | K2: 0.3 | L2: 0 | M2: 0.2 | N2: 0.5 | O2: 0 | P2: 0 | Q2: 0 | R2: 1 | S2: 1 | T2: 1 | U2: 1 | V2: 1 | W2: 0 | X2: 1 | Y2: 1 | Z2: 1 | AA2: 0 | AB2: 1 | AC2: 1 | AD2: 1 | AE2: 1 | AF2: 0 | AG2: 1 | AH2: 1
A3: NO | B3: 0.3 | C3: 0.2 | D3: 0.3 | E3: 0 | F3: 0 | G3: 0 | H3: 0.5 | I3: 0 | J3: 0.4 | K3: 0 | L3: 0 | M3: 0.2 | N3: 0.5 | O3: 0 | P3: 0 | Q3: 0 | R3: 1 | S3: 0 | T3: 1 | U3: 1 | V3: 1 | W3: 0 | X3: 1 | Y3: 1 | Z3: 1 | AA3: 0 | AB3: 1 | AC3: 1 | AD3: 1 | AE3: 1 | AF3: 1 | AG3: 1 | AH3: 0.5
A4: NO | B4: 0.7 | C4: 0.2 | D4: 0.2 | E4: 0.7 | F4: 1 | G4: 0.9 | H4: 1 | I4: 0.84810127 | J4: 0.4 | K4: 0.5 | L4: 0.5 | M4: 0.26216216 | N4: 0.5 | O4: 1 | P4: 0.050632911 | Q4: 0.5 | R4: 1 | S4: 1 | T4: 1 | U4: 1 | V4: 1 | W4: 1 | X4: 1 | Y4: 1 | Z4: 1 | AA4: 1 | AB4: 1 | AC4: 1 | AD4: 1 | AE4: 1 | AF4: 1 | AG4: 1 | AH4: 1
A5: NO | B5: 0.5 | C5: 0 | D5: 0 | E5: 1 | F5: 0.3 | G5: 1 | H5: 0.5 | I5: 1 | J5: 0.6 | K5: 1 | L5: 0 | M5: 0 | N5: 1 | O5: 0 | P5: 0 | Q5: 0 | R5: 1 | S5: 1 | T5: 1 | U5: 1 | V5: 1 | W5: 0 | X5: 1 | Y5: 1 | Z5: 0 | AA5: 1 | AB5: 1 | AC5: 1 | AD5: 1 | AE5: 1 | AF5: 0 | AG5: 1 | AH5: 1
A6: YES | B6: 0.7 | C6: 0.2 | D6: 0.3 | E6: 0.7 | F6: 0 | G6: 1 | H6: 0.5 | I6: 1 | J6: 0.2 | K6: 0 | L6: 0 | M6: 0 | N6: 1 | O6: 0 | P6: 0 | Q6: 0 | R6: 1 | S6: 0 | T6: 1 | U6: 1 | V6: 1 | W6: 0 | X6: 1 | Y6: 1 | Z6: 1 | AA6: 0 | AB6: 1 | AC6: 1 | AD6: 1 | AE6: 1 | AF6: 1 | AG6: 1 | AH6: 1
A7: NO | B7: 0.7 | C7: 0.2 | D7: 0.3 | E7: 0.7 | F7: 0 | G7: 1 | H7: 0.5 | I7: 1 | J7: 0.2 | K7: 0 | L7: 0 | M7: 0.2 | N7: 0.2 | O7: 0 | P7: 0 | Q7: 0 | R7: 0 | S7: 0 | T7: 1 | U7: 1 | V7: 1 | W7: 0 | X7: 1 | Y7: 1 | Z7: 0 | AA7: 0 | AB7: 1 | AC7: 1 | AD7: 1 | AE7: 1 | AF7: 1 | AG7: 1 | AH7: 0.5
A8: NO | B8: 0.7 | C8: 0 | D8: 0 | E8: 1 | F8: 0.3 | G8: 1 | H8: 0.5 | I8: 1 | J8: 0.8 | K8: 0 | L8: 0 | M8: 1 | N8: 0.5 | O8: 0 | P8: 0 | Q8: 0 | R8: 1 | S8: 1 | T8: 1 | U8: 1 | V8: 1 | W8: 0 | X8: 1 | Y8: 1 | Z8: 1 | AA8: 1 | AB8: 1 | AC8: 1 | AD8: 1 | AE8: 1 | AF8: 0 | AG8: 1 | AH8: 0.5
A9: NO | B9: 0.9 | C9: 0 | D9: 1 | E9: 1 | F9: 0.3 | G9: 1 | H9: 0.5 | I9: 1 | J9: 0.4 | K9: 0 | L9: 0 | M9: 0.2 | N9: 0.5 | O9: 0 | P9: 0 | Q9: 0 | R9: 1 | S9: 0 | T9: 1 | U9: 1 | V9: 1 | W9: 0 | X9: 1 | Y9: 1 | Z9: 1 | AA9: 0 | AB9: 1 | AC9: 1 | AD9: 1 | AE9: 1 | AF9: 1 | AG9: 1 | AH9: 0.5
A10: NO | B10: 0.2 | C10: 0.1 | D10: 0.2 | E10: 0.5 | F10: 0.1 | G10: 0.9 | H10: 0.55416667 | I10: 0.84810127 | J10: 0.42278481 | K10: 0.13055556 | L10: 0.05 | M10: 0.26216216 | N10: 0.515625 | O10: 0.075 | P10: 0.050632911 | Q10: 0.1 | R10: 0.9382716 | S10: 0.38271605 | T10: 0.96296296 | U10: 1 | V10: 1 | W10: 0.12345679 | X10: 0.96296296 | Y10: 0.95061728 | Z10: 0.75308642 | AA10: 0.35802469 | AB10: 0.98765432 | AC10: 1 | AD10: 0.97530864 | AE10: 1 | AF10: 0.4625 | AG10: 1 | AH10: 0.8961039
A11: YES | B11: 0.3 | C11: 0.1 | D11: 0.2 | E11: 0.5 | F11: 0.1 | G11: 0.9 | H11: 0.55416667 | I11: 0.84810127 | J11: 0.42278481 | K11: 0.13055556 | L11: 0.05 | M11: 0.26216216 | N11: 0.515625 | O11: 0.075 | P11: 0.050632911 | Q11: 0.1 | R11: 0.9382716 | S11: 0.38271605 | T11: 0.96296296 | U11: 1 | V11: 1 | W11: 0.12345679 | X11: 0.96296296 | Y11: 0.95061728 | Z11: 0.75308642 | AA11: 0.35802469 | AB11: 0.98765432 | AC11: 1 | AD11: 0.97530864 | AE11: 1 | AF11: 0.4625 | AG11: 1 | AH11: 0.8961039
A12: YES | B12: 1 | C12: 0 | D12: 0 | E12: 0 | F12: 0 | G12: 1 | H12: 0.5 | I12: 1 | J12: 0.6 | K12: 0 | L12: 0 | M12: 0.2 | N12: 0.5 | O12: 0 | P12: 0 | Q12: 0 | R12: 1 | S12: 0 | T12: 1 | U12: 1 | V12: 1 | W12: 0 | X12: 1 | Y12: 1 | Z12: 1 | AA12: 0 | AB12: 1 | AC12: 1 | AD12: 1 | AE12: 1 | AF12: 0 | AG12: 1 | AH12: 1
A13: NO | B13: 0.5 | C13: 0 | D13: 0 | E13: 0 | F13: 0 | G13: 1 | H13: 0.5 | I13: 1 | J13: 0.6 | K13: 0 | L13: 0 | M13: 0.2 | N13: 0.5 | O13: 0 | P13: 0 | Q13: 0 | R13: 1 | S13: 0 | T13: 1 | U13: 1 | V13: 1 | W13: 0 | X13: 1 | Y13: 1 | Z13: 1 | AA13: 0 | AB13: 1 | AC13: 1 | AD13: 1 | AE13: 1 | AF13: 0 | AG13: 1 | AH13: 1
... A21: ? | B21: 0.3 | C21: 0 | D21: 0 | E21: 0.7 | F21: 0 | G21: 1 | H21: 0.5 | I21: 1 | J21: 0.6 | K21: 0 | L21: 0 | M21: 0.2 | N21: 0.5 | O21: 0 | P21: 0 | Q21: 0 | R21: 1 | S21: 1 | T21: 1 | U21: 1 | V21: 1 | W21: 0 | X21: 1 | Y21: 1 | Z21: 1 | AA21: 1 | AB21: 1 | AC21: 1 | AD21: 1 | AE21: 1 | AF21: 0 | AG21: 1 | AH21: 1
A23: No | B23: Atribut | D23: YES | E23: NO | F23: TOTAL | G23: Entropy | H23: Information Gain
B24: Node 1 | C24: Kategori | D24: 4 | E24: 8 | F24: 12
A25: 1 | B25: Anggota ART | N25: ASAL | O25: PRED | Q25: CONFLUSION MATRIX
C26: <=0,5 | D26: 0 | E26: 9 | F26: =SUM(D26:E26) -> 9 | G26: 0 | H26: =F28-((F26/12)*G26)-((F27/12)*G27) -> 10 | N26: NO | O26: NO
C27: >0,5 | D27: 1 | E27: 0 | F27: =SUM(D27:E27) -> 1 | G27: 0 | N27: NO | O27: NO | Q27: NBC | S27: KELAS ASAL | U27: PRECISION
D28: =SUM(D26:D27) -> 1 | E28: =SUM(E26:E27) -> 9 | F28: =SUM(D28:E28) -> 10 | N28: NO | O28: NO | S28: YES | T28: NO
A29: 2 | B29: Status bangunan | N29: NO | O29: NO | Q29: PRED | R29: YES | S29: 0 | T29: 0 | U29: 0
C30: 0.1 | D30: 0 | E30: 6 | F30: =SUM(D30:E30) -> 6 | G30: 0 | H30: =F32-((F30/12)*G30)-((F31/12)*G31) -> 9.729574 | N30: NO | O30: NO | R30: NO | S30: 1 | T30: 7 | U30: =T30/(S30+T30) -> 0.875
C31: 0.2 | D31: =COUNTIFS($C$2:$C$13,C31,$A$2:$A$13,$D$23) -> 1 | E31: 3 | F31: =SUM(D31:E31) -> 4 | G31: =((-D31/F31)*IMLOG2(D31/F31)+(-E31/F31)*IMLOG2(E31/F31)) -> 0.81127812 | N31: NO | O31: NO | Q31: RECALL | S31: =S29/(S29+S30) -> 0 | T31: =T30/(T29+T30) -> 1
D32: 1 | E32: 9 | F32: 10 | N32: NO | O32: NO
A33: 3 | B33: Status lahan | N33: YES | O33: NO | Q33: AKURASI | U33: =(S29+T30)/(S29+T29+S30+T30) -> 0.875
C34: <=0,25 | D34: 1 | E34: 3 | F34: 4 | G34: =((-D34/F34)*IMLOG2(D34/F34)+(-E34/F34)*IMLOG2(E34/F34)) -> 0.81127812 | H34: =F36-((F34/12)*G34)-((F35/12)*G35) -> 8.729574
C35: >0,25 | D35: 0 | E35: 6 | F35: 6 | G35: 0
D36: 1 | E36: 9 | F36: 9
A37: 4 | B37: Jenis Lantai
C38: <=0,75 | D38: 1 | E38: 9 | F38: 10 | G38: =((-D38/F38)*IMLOG2(D38/F38)+(-E38/F38)*IMLOG2(E38/F38)) -> 0.46899559 | H38: =F40-((F38/12)*G38)-((F39/12)*G39) -> 9.6091703
C39: >0,75 | D39: 0 | E39: 0 | F39: 0 | G39: 0
D40: 2 | E40: 5 | F40: 10
A41: 5 | B41: Jenis Dinding
C42: <=0,25 | D42: 0 | E42: 8 | F42: 8 | G42: 0 | H42: =F44-((F42/12)*G42)-((F43/12)*G43) -> 9.8333333
C43: >0,25 | D43: 1 | E43: 1 | F43: 2 | G43: =((-D43/F43)*IMLOG2(D43/F43)+(-E43/F43)*IMLOG2(E43/F43)) -> 1
D44: 1 | E44: 9 | F44: 10
A45: 6 | B45: Kondisi Dinding
C46: <=0,75 | D46: 0 | E46: 0 | F46: 0 | G46: 0 | H46: =F48-((F46/12)*G46)-((F47/12)*G47) -> 9.6091703
C47: >0,75 | D47: 1 | E47: 9 | F47: 10 | G47: =((-D47/F47)*IMLOG2(D47/F47)+(-E47/F47)*IMLOG2(E47/F47)) -> 0.46899559
D48: 1 | E48: 9 | F48: 10
...
